Workbook

Sheet 本部部署（重複）
A1: 異動先事業本部 | B1: 異動先部 | C1: 異動先G
A2: CS本部 | B2: CS部 | C2: 運用G
A3: CS本部 | B3: CS本部(部なし) | C3: CS本部(Gなし)
A4: CS本部 | B4: CS部 | C4: CREG
A5: CS本部 | B5: CS部 | C5: CREG
A6: CS本部 | B6: CS本部(部なし) | C6: CS本部(Gなし)
A7: CS本部 | B7: CS部 | C7: 運用G
A8: CS本部 | B8: CS部 | C8: CREG
A9: CS本部 | B9: CX部 | C9: CX部(Gなし)
A10: CS本部 | B10: CX部 | C10: EnhancementG
A11: CS本部 | B11: CS部 | C11: 運用G
A12: CS本部 | B12: CX部 | C12: EnhancementG
... A4031: 内部監査室本部格 | B4031: 内部監査室 | C4031: 内部監査G
A4033: ここからは全角に戻した値
A4034: ＣＳ本部 | B4034: ＣＳ部 | C4034: 運用Ｇ
A4035: ＣＳ本部 | B4035: ＣＳ本部（部なし） | C4035: ＣＳ本部（Ｇなし）
A4036: ＣＳ本部 | B4036: ＣＳ部 | C4036: ＣＲＥＧ
A4037: ＣＳ本部 | B4037: ＣＳ部 | C4037: ＣＲＥＧ
A4038: ＣＳ本部 | B4038: ＣＳ本部（部なし） | C4038: ＣＳ本部（Ｇなし）
A4039: ＣＳ本部 | B4039: ＣＳ部 | C4039: 運用Ｇ
A4040: ＣＳ本部 | B4040: ＣＳ部 | C4040: ＣＲＥＧ
A4041: ＣＳ本部 | B4041: ＣＸ部 | C4041: ＣＸ部（Ｇなし）
A4042: ＣＳ本部 | B4042: ＣＸ部 | C4042: ＥｎｈａｎｃｅｍｅｎｔＧ
A4043: ＣＳ本部 | B4043: ＣＳ部 | C4043: 運用Ｇ
A4044: ＣＳ本部 | B4044: ＣＸ部 | C4044: ＥｎｈａｎｃｅｍｅｎｔＧ
A4045: ＣＳ本部 | B4045: ＣＸ部 | C4045: ＥｎｈａｎｃｅｍｅｎｔＧ
... A8063: 内部監査室本部格 | B8063: 内部監査室 | C8063: 内部監査Ｇ

Sheet 概要
A1: 集計
A2: 項目（div） | B2: 総数 | C2: 合致 | D2: 0file | E2: 仮説 | F2: 不明
A3: div | B3: 497 | C3: 95 | D3: 278 | E3: 100 | F3: 24
A4: 項目（project） | B4: 総数 | C4: 在籍 | D4: 退職（部署判明） | E4: 退職（部署不明） | F4: 管理者不明
A5: Project | B5: 265 | C5: 197 | D5: 33 | E5: 35 | F5: 9
A6: 総 | B6: =SUM(B3:B5) -> 762
A8: divフィルター詳細
A9: フィルタ名 | B9: 内容 | E9: 今後の動き
A10: 合致 | B10: 0fileを除いた、あたりがついているフォルダ | E10: 佑さんの部署遍歴から、仮説の箇所などを判明していく
A11: 0file | B11: ファイル数0で利用していないフォルダ | E11: 各フォルダ詳細から、ホットフォルダとコールドフォルダを分けて分別していく
A12: 仮説 | B12: 0fileを除いた、仮説で記載した項目の内容 仮説も立てられないものは（不明）でカウント ※E列 | E12: 本部と部室を繋げて本当に相違ないか確認予定
A13: 不明 | B13: 0fileを除いた、仮説も立てられないもの | E13: 仮説での本部長/部室長が不明な箇所にもあたりを付けて確認予定
E14: 仮説→あたりを付けられないものは、不明にする
A16: Projectフィルター詳細
A17: フィルタ名 | B17: 内容 | E17: 今後の動き
A18: 在籍 | B18: 管理者が判明している | E18: 各フォルダ詳細から、ホットフォルダとコールドフォルダを分けて分別していく
A19: 退職（部署判明） | B19: 管理者がすでに退職しているが、部署は判明している
A20: 退職（部署不明） | B20: 管理者がすでに退職しており、部署も不明
A21: 管理者不明 | B21: フォルダ管理者が不明のためこれ以上どうしようもない
A23: 本部長、部室長の今あたっていない人を再度あてる 半角カタカナを書き直して
A24: 1列でステータスをわかりやすく、フィルターで単発で表示できるように集計は確定するまで各自に任す、だれが見ても一発でわかるステータスなどにする

Sheet データ仕分け残対応
A1: 項番 | B1: フォルダ枠 | C1: 担当者 | D1: 概要 | E1: ステータス
A2: 1 | B2: div | C2: 戸谷 | D2: 0fileの管理者を特定。 不明なものは不明に変更 | E2: 済
A3: 2 | B3: project | C3: 戸谷 | D3: 最終更新日3年までのものを出して、 AWSとGoogleドライブに分ける | E3: 済
A4: 3 | B4: project | C4: 戸谷 | D4: file数をフォルダごとにあてる →PF側？の作業待ち | E4: 作業待ち
A5: 4 | B5: project | C5: PF | D5: projectフォルダのファイル数を出す
A6: 5 | B6: div | C6: 戸谷 | D6: 管理者不明のところを少し深ぼる | E6: 済
A7: 6 | B7: project | C7: 那須さん | D7: 管理者が不明な箇所の確認先の特定
A8: 7 | B8: project | C8: 戸谷 | D8: 管理者ごとにフォルダの行を追加して、全員退職なら退職などにフラグを変更する 関数を使っていない箇所があるので、もう一度さらう ●関数 ・在籍：=XLOOKUP(G5,'従業員情報'!$A:$A,'従業員情報'!$N:$N,"×") ・退職：=XLOOKUP(G5,'退職者'!$C:$C,'退職者'!$B:$B,"×")&XLOOKUP(G18,'退職者'!$C:$C,'退職者'!$A:$A,"×") ●ステータス ・在籍にヒット＝在籍 ・退職にヒット＝退職 ・退職でもヒットしない＝退職（部署不明） ・管理者の記載のない箇所＝管理者不明（那須さんに個別確認を依頼） | E8: 済
A9: 8 | B9: project | C9: 戸谷 | D9: 列ごとの項目をdivに揃える | E9: 済
A13: 質問
A14: 項番 | B14: フォルダ枠 | D14: 概要 | E14: ステータス | F14: 回答 | G14: 備考
A15: 1 | B15: div | D15: 0fileでも無い最終更新日が無いフォルダを出していただきたい | E15: 済 | F15: データ出力に時間かかるため、一旦はたかん以外はAWSを移行先に指定 守田）11/6時点で一応佐藤さんにデータ出力依頼をしてます。
A16: 2 | B16: project | D16: 容量と最終更新日のシートに記載のないものがあるので出してほしい。 記載のないものは0file or 0容量であれば教えていただきたい | E16: 対応中 | F16: 守田）容量はすべて埋めました。2件だけ#N/Aが存在しますが移行不要でOKです。 最終更新日はないものがちらほらあるので佐藤さんに依頼中です。
A17: 3 | B17: project | D17: projectフォルダのファイル数を算出していただける流れだったと思いますが、そちらは不要になった状況でしょうか？ | E17: 対応中 | F17: 守田）11/6時点で出力中なので少々お待ちを

Sheet （旧）div
A1: div topフォルダ | D1: 本部・本部 | E1: 部室・部室 | F1: 本部・部室 | G1: 部室・本部 | H1: 仮説
A2: スタジオフンザ | C2: 仮説 | E2: 廃止 | G2: × | H2: × | I2: 廃止 | K2: {=XLOOKUP($B2,'部署遍歴'!C:C,'部署遍歴'!D:D,"×")} -> ×
A3: デジタルエンターテインメント事業本部 | C3: 仮説 | E3: 各事業部 (モンスト事業部など) / 開発本部 | G3: × | H3: × | I3: 各事業部 (モンスト事業部など) / 開発本部 | J3: 事業本部制の廃止に伴い、事業や機能ごとに再編されました。 | K3: {=XLOOKUP($B3,'部署遍歴'!C:C,'部署遍歴'!D:D,"×")} -> ×
A4: ミクシィマーケティング | C4: 仮説 | E4: デザイン本部 / 各事業部 | G4: × | H4: × | I4: デザイン本部 / 各事業部 | J4: 全社機能は「デザイン本部」へ、プロダクトごとの機能は各事業部へ移管されたと推測されます。 | K4: {=XLOOKUP($B4,'部署遍歴'!C:C,'部署遍歴'!D:D,"×")} -> ×
A5: 渉外部 | E5: 渉外部本部格 | G5: × | H5: × | K5: {=XLOOKUP($B5,'部署遍歴'!C:C,'部署遍歴'!D:D,"×")} -> ×
A6: 事業デザイン本部 | C6: 仮説 | E6: デザイン本部 | G6: × | H6: × | I6: デザイン本部 | J6: 名称変更、または機能統合された可能性が高いです。 | K6: {=XLOOKUP($B6,'部署遍歴'!C:C,'部署遍歴'!D:D,"×")} -> ×
A7: コーポレートサポート本部 | C7: 仮説 | E7: はたらく環境推進本部 | G7: 平山 英輝 | H7: × | I7: はたらく環境推進本部 | J7: 総務や情報システムなどの機能が引き継がれました。 | K7: {=XLOOKUP($B7,'部署遍歴'!C:C,'部署遍歴'!D:D,"×")} -> ×
A8: 人事部 | C8: 仮説 | E8: 人事本部 | G8: 杉村 元規 | H8: × | I8: 人事本部 | J8: 名称変更、または機能強化による再編です。 | K8: {=XLOOKUP($B8,'部署遍歴'!C:C,'部署遍歴'!D:D,"×")} -> ×
A9: XFLAG ENTERTAINMENT | C9: 仮説 | E9: 開発本部 / デザイン本部 / 各事業部 | G9: × | H9: × | I9: 開発本部 / デザイン本部 / 各事業部 | J9: XFLAGブランドのMIXI本体への統合に伴い、機能が分散・再編されました。 | K9: {=XLOOKUP($B9,'部署遍歴'!C:C,'部署遍歴'!D:D,"×")} -> ×
A10: 会長室 | C10: 仮説 | E10: 社長室 | G10: × | H10: × | I10: 社長室 | J10: 名称変更、または機能統合された可能性が高いです。 | K10: {=XLOOKUP($B10,'部署遍歴'!C:C,'部署遍歴'!D:D,"×")} -> ×
A11: 人事部付 | C11: 仮説 | E11: 特定の役職のため、部署としての再編先はなし | G11: × | H11: × | I11: 特定の役職のため、部署としての再編先はなし | J11: 部署名ではなく、特定の役職としての位置づけのため、現存する部署への再編はありません。 | K11: {=XLOOKUP($B11,'部署遍歴'!C:C,'部署遍歴'!D:D,"×")} -> ×
A12: メディアコンテンツ事業本部 | C12: 仮説 | E12: 廃止（一部機能は他部署へ移管） | G12: × | H12: × | I12: 廃止（一部機能は他部署へ移管） | J12: 直接の後継部署は見当たらず、個別の事業は終了または他部署へ移管されたようです。 | K12: {=XLOOKUP($B12,'部署遍歴'!C:C,'部署遍歴'!D:D,"×")} -> ×
A13: 経営企画本部 | C13: 仮説 | E13: 経営推進本部 → コーポレートデベロップメント本部 など | G13: × | H13: × | I13: 経営推進本部 → コーポレートデベロップメント本部 など | J13: 「経営推進本部」を経て、機能が分散・再編されたと推測されます。 | K13: {=XLOOKUP($B13,'部署遍歴'!C:C,'部署遍歴'!D:D,"×")} -> ×
A14: XFLAG ARTS | C14: 仮説 | E14: 開発本部 / デザイン本部 / 各事業部 | G14: × | H14: × | I14: 開発本部 / デザイン本部 / 各事業部 | J14: XFLAGブランドのMIXI本体への統合に伴い、機能が分散・再編されました。 | K14: {=XLOOKUP($B14,'部署遍歴'!C:C,'部署遍歴'!D:D,"×")} -> ×
A15: スマートヘルス | C15: 仮説 | E15: 廃止（事業終了または他部署へ移管） | G15: × | H15: × | I15: 廃止（事業終了または他部署へ移管） | J15: 現在の組織図には見当たらず、事業としては終了または移管されたようです。 | K15: {=XLOOKUP($B15,'部署遍歴'!C:C,'部署遍歴'!D:D,"×")} -> ×
A16: コンプライアンス本部 | E16: ｺﾝﾌﾟﾗｲｱﾝｽ本部 | G16: × | H16: × | K16: {=XLOOKUP($B16,'部署遍歴'!C:C,'部署遍歴'!D:D,"×")} -> ×
A17: ヴァンテージスタジオ | C17: 仮説 | E17: 廃止 | G17: × | H17: × | I17: 廃止 | J17: 現在の組織図には見当たりません。 | K17: {=XLOOKUP($B17,'部署遍歴'!C:C,'部署遍歴'!D:D,"×")} -> ×
A18: 内部監査室 | E18: 内部監査室本部格 | G18: × | H18: × | K18: {=XLOOKUP($B18,'部署遍歴'!C:C,'部署遍歴'!D:D,"×")} -> ×
A19: チケットキャンプ事業部 | C19: 仮説 | E19: 廃止（事業終了） | G19: × | H19: × | I19: 廃止（事業終了） | J19: 事業が終了しました。 | K19: {=XLOOKUP($B19,'部署遍歴'!C:C,'部署遍歴'!D:D,"×")} -> ×
A20: オレンジスタジオ | C20: 仮説 | E20: MIXI M事業部 オレンジグループ | G20: × | H20: × | I20: MIXI M事業部 オレンジグループ | J20: 「MIXI M事業部」内のグループとして存続している可能性があります。 | K20: {=XLOOKUP($B20,'部署遍歴'!C:C,'部署遍歴'!D:D,"×")} -> ×
A21: ゲーム事業本部 | C21: 仮説 | E21: 各事業部 (モンスト事業部など) | G21: × | H21: × | I21: 各事業部 (モンスト事業部など) | J21: 事業本部制の廃止に伴い、事業ごとに再編されました。 | K21: {=XLOOKUP($B21,'部署遍歴'!C:C,'部署遍歴'!D:D,"×")} -> ×
A22: モンスト事業本部 | C22: 仮説 | E22: モンスト事業部 | G22: × | H22: × | I22: モンスト事業部 | J22: モンスト関連の部署は、現在の「モンスト事業部」に集約・再編されました。 | K22: {=XLOOKUP($B22,'部署遍歴'!C:C,'部署遍歴'!D:D,"×")} -> ×
A24: div 1階層目フォルダ
A25: アドテクスタジオ | B25: アドテクG | C25: 廃止/再編 | D25: {=XLOOKUP($A25,'本部部署'!A:A,'本部部署'!A:A,"×",0,"1")} -> × | E25: {=XLOOKUP($B25,'本部部署'!B:B,'本部部署'!B:B,"×",0,"1")} -> × | F25: {=XLOOKUP($A25,'本部部署'!B:B,'本部部署'!B:B,"×",0,"1")} -> × | G25: {=XLOOKUP($B25,'本部部署'!A:A,'本部部署'!A:A,"×",0,"1")} -> × | H25: 開発本部 / デザイン本部
A26: アドテクスタジオ | B26: 企画G | C26: 廃止/再編 | D26: {=XLOOKUP($A26,'本部部署'!A:A,'本部部署'!A:A,"×",0,"1")} -> × | E26: {=XLOOKUP($B26,'本部部署'!B:B,'本部部署'!B:B,"×",0,"1")} -> × | F26: {=XLOOKUP($A26,'本部部署'!B:B,'本部部署'!B:B,"×",0,"1")} -> × | G26: {=XLOOKUP($B26,'本部部署'!A:A,'本部部署'!A:A,"×",0,"1")} -> × | H26: 開発本部 / デザイン本部
A27: アドテクスタジオ | B27: 開発G | C27: 廃止/再編 | D27: {=XLOOKUP($A27,'本部部署'!A:A,'本部部署'!A:A,"×",0,"1")} -> × | E27: {=XLOOKUP($B27,'本部部署'!B:B,'本部部署'!B:B,"×",0,"1")} -> × | F27: {=XLOOKUP($A27,'本部部署'!B:B,'本部部署'!B:B,"×",0,"1")} -> × | G27: {=XLOOKUP($B27,'本部部署'!A:A,'本部部署'!A:A,"×",0,"1")} -> × | H27: 開発本部 / デザイン本部
A28: アドテクスタジオ | B28: 室共有 | C28: 廃止/再編 | D28: {=XLOOKUP($A28,'本部部署'!A:A,'本部部署'!A:A,"×",0,"1")} -> × | E28: {=XLOOKUP($B28,'本部部署'!B:B,'本部部署'!B:B,"×",0,"1")} -> × | F28: {=XLOOKUP($A28,'本部部署'!B:B,'本部部署'!B:B,"×",0,"1")} -> × | G28: {=XLOOKUP($B28,'本部部署'!A:A,'本部部署'!A:A,"×",0,"1")} -> × | H28: -
A29: メディア事業本部 | B29: mixiゲーム部 | C29: 廃止/再編 | D29: {=XLOOKUP($A29,'本部部署'!A:A,'本部部署'!A:A,"×",0,"1")} -> × | E29: {=XLOOKUP($B29,'本部部署'!B:B,'本部部署'!B:B,"×",0,"1")} -> × | F29: {=XLOOKUP($A29,'本部部署'!B:B,'本部部署'!B:B,"×",0,"1")} -> × | G29: {=XLOOKUP($B29,'本部部署'!A:A,'本部部署'!A:A,"×",0,"1")} -> × | H29: ゲーム事業部
A30: メディア事業本部 | B30: mixiサービス部 | C30: 廃止/再編 | D30: {=XLOOKUP($A30,'本部部署'!A:A,'本部部署'!A:A,"×",0,"1")} -> × | E30: {=XLOOKUP($B30,'本部部署'!B:B,'本部部署'!B:B,"×",0,"1")} -> × | F30: {=XLOOKUP($A30,'本部部署'!B:B,'本部部署'!B:B,"×",0,"1")} -> × | G30: {=XLOOKUP($B30,'本部部署'!A:A,'本部部署'!A:A,"×",0,"1")} -> × | H30: MIXI M事業部
A31: メディア事業本部 | B31: 本部共有 | C31: 廃止/再編 | D31: {=XLOOKUP($A31,'本部部署'!A:A,'本部部署'!A:A,"×",0,"1")} -> × | E31: {=XLOOKUP($B31,'本部部署'!B:B,'本部部署'!B:B,"×",0,"1")} -> × | F31: {=XLOOKUP($A31,'本部部署'!B:B,'本部部署'!B:B,"×",0,"1")} -> × | G31: {=XLOOKUP($B31,'本部部署'!A:A,'本部部署'!A:A,"×",0,"1")} -> × | H31: -
A32: メディア事業本部 | B32: mixiコンテンツ部 | C32: 廃止/再編 | D32: {=XLOOKUP($A32,'本部部署'!A:A,'本部部署'!A:A,"×",0,"1")} -> × | E32: {=XLOOKUP($B32,'本部部署'!B:B,'本部部署'!B:B,"×",0,"1")} -> × | F32: {=XLOOKUP($A32,'本部部署'!B:B,'本部部署'!B:B,"×",0,"1")} -> × | G32: {=XLOOKUP($B32,'本部部署'!A:A,'本部部署'!A:A,"×",0,"1")} -> × | H32: MIXI M事業部
A33: メディア事業本部 | B33: mixiシステム部 | C33: 廃止/再編 | D33: {=XLOOKUP($A33,'本部部署'!A:A,'本部部署'!A:A,"×",0,"1")} -> × | E33: {=XLOOKUP($B33,'本部部署'!B:B,'本部部署'!B:B,"×",0,"1")} -> × | F33: {=XLOOKUP($A33,'本部部署'!B:B,'本部部署'!B:B,"×",0,"1")} -> × | G33: {=XLOOKUP($B33,'本部部署'!A:A,'本部部署'!A:A,"×",0,"1")} -> × | H33: MIXI M事業部
A34: Diverseスタジオ | B34: インドマーケット部 | C34: 廃止/分社化 | D34: {=XLOOKUP($A34,'本部部署'!A:A,'本部部署'!A:A,"×",0,"1")} -> × | E34: {=XLOOKUP($B34,'本部部署'!B:B,'本部部署'!B:B,"×",0,"1")} -> × | F34: {=XLOOKUP($A34,'本部部署'!B:B,'本部部署'!B:B,"×",0,"1")} -> × | G34: {=XLOOKUP($B34,'本部部署'!A:A,'本部部署'!A:A,"×",0,"1")} -> × | H34: 株式会社Diverse
A35: Diverseスタジオ | B35: かいはつ室 | C35: 廃止/分社化 | D35: {=XLOOKUP($A35,'本部部署'!A:A,'本部部署'!A:A,"×",0,"1")} -> × | E35: {=XLOOKUP($B35,'本部部署'!B:B,'本部部署'!B:B,"×",0,"1")} -> × | F35: {=XLOOKUP($A35,'本部部署'!B:B,'本部部署'!B:B,"×",0,"1")} -> × | G35: {=XLOOKUP($B35,'本部部署'!A:A,'本部部署'!A:A,"×",0,"1")} -> × | H35: 株式会社Diverse
A36: Diverseスタジオ | B36: ビジネス推進室 | C36: 廃止/分社化 | D36: {=XLOOKUP($A36,'本部部署'!A:A,'本部部署'!A:A,"×",0,"1")} -> × | E36: {=XLOOKUP($B36,'本部部署'!B:B,'本部部署'!B:B,"×",0,"1")} -> × | F36: {=XLOOKUP($A36,'本部部署'!B:B,'本部部署'!B:B,"×",0,"1")} -> × | G36: {=XLOOKUP($B36,'本部部署'!A:A,'本部部署'!A:A,"×",0,"1")} -> × | H36: 株式会社Diverse
... A38: Diverseスタジオ | B38: Poiboy事業部 | C38: 廃止/分社化 | D38: {=XLOOKUP($A38,'本部部署'!A:A,'本部部署'!A:A,"×",0,"1")} -> × | E38: {=XLOOKUP($B38,'本部部署'!B:B,'本部部署'!B:B,"×",0,"1")} -> × | F38: {=XLOOKUP($A38,'本部部署'!B:B,'本部部署'!B:B,"×",0,"1")} -> × | G38: {=XLOOKUP($B38,'本部部署'!A:A,'本部部署'!A:A,"×",0,"1")} -> × | H38: 株式会社Diverse
A39: Diverseスタジオ | B39: 経営管理部 | D39: {=XLOOKUP($A39,'本部部署'!A:A,'本部部署'!A:A,"×",0,"1")} -> × | E39: {=XLOOKUP($B39,'本部部署'!B:B,'本部部署'!B:B,"×",0,"1")} -> 経営管理部
A40: Diverseスタジオ | B40: 結婚支援事業部 | C40: 廃止/分社化 | D40: {=XLOOKUP($A40,'本部部署'!A:A,'本部部署'!A:A,"×",0,"1")} -> × | E40: {=XLOOKUP($B40,'本部部署'!B:B,'本部部署'!B:B,"×",0,"1")} -> × | F40: {=XLOOKUP($A40,'本部部署'!B:B,'本部部署'!B:B,"×",0,"1")} -> × | G40: {=XLOOKUP($B40,'本部部署'!A:A,'本部部署'!A:A,"×",0,"1")} -> × | H40: 株式会社Diverse
A41: Diverseスタジオ | B41: 新規サービス事業部 | C41: 廃止/分社化 | D41: {=XLOOKUP($A41,'本部部署'!A:A,'本部部署'!A:A,"×",0,"1")} -> × | E41: {=XLOOKUP($B41,'本部部署'!B:B,'本部部署'!B:B,"×",0,"1")} -> × | F41: {=XLOOKUP($A41,'本部部署'!B:B,'本部部署'!B:B,"×",0,"1")} -> × | G41: {=XLOOKUP($B41,'本部部署'!A:A,'本部部署'!A:A,"×",0,"1")} -> × | H41: 株式会社Diverse
A42: Diverseスタジオ | B42: youbride事業部 | C42: 廃止/分社化 | D42: {=XLOOKUP($A42,'本部部署'!A:A,'本部部署'!A:A,"×",0,"1")} -> × | E42: {=XLOOKUP($B42,'本部部署'!B:B,'本部部署'!B:B,"×",0,"1")} -> × | F42: {=XLOOKUP($A42,'本部部署'!B:B,'本部部署'!B:B,"×",0,"1")} -> × | G42: {=XLOOKUP($B42,'本部部署'!A:A,'本部部署'!A:A,"×",0,"1")} -> × | H42: 株式会社Diverse
...

Sheet (旧)project
A1: 管理者退職済み（管理者不明） | E1: 69(10)
A2: 退職フラグのもので、「無記載/無/無し＝退職Jiraに記載なし」、「×＝退職Jiraが起票されていないor記載ミス」
A4: Project topフォルダ | B4: フラグ | C4: 管理者 | D4: C列部署 | E4: 管理者 | F4: 部署 | G4: 管理者 | H4: 部署 | I4: 管理者 | J4: 部署 | K4: 管理者 | L4: 部署 | M4: 管理者 | N4: 部署 | O4: 管理者 | P4: 部署 | Q4: 管理者 | R4: 部署 | S4: 管理者 | T4: 部署 | U4: 退職者部署 | V4: 退職者部署
A5: PJ_F1 | C5: 島村 恒平 | D5: 取締役 | E5: 島村恒平
A6: 共有スケジュール | C6: 長谷川 純子 | D6: コーポレートファイナンス本部/経理税務部/経理グループ | E6: 長谷川純子
A7: group-ip | C7: 村津 文武 | D7: コンプライアンス本部/知財室/商標・著作権グループ | E7: 村津文武
A8: DSP | C8: 尾関 芳郎 | D8: みてね事業本部/みてねプラットフォーム部/SREグループ | E8: 尾関芳郎
A9: ミクシィリサーチ経理業務 | C9: 長岡 輝 | D9: Vantageスタジオ/Romi事業部/UX企画グループ | E9: 長岡輝
A10: UXDワーキンググループ | C10: 藤崎 宏司 | D10: Vantageスタジオ/事業推進室/mercuryグループ | E10: 藤崎宏司
A11: ミクシィグループWebクリッピング | C11: 木下智子、菊池翔平、池谷洋平、寺岡浩史、町井香織、古澤祐幸 | D11: 経営推進本部/広報部/インターナルコミュニケーショングループ/インターナルコミュニケーションチーム | E11: 木下智子 | F11: 経営推進本部/広報部 | G11: 菊池翔平 | H11: 経営推進本部/広報部/サステナビリティ推進グループ | I11: 池谷 洋平 | J11: 経営推進本部/広報部/サステナビリティ推進グループ/次世代育成支援チーム | K11: 寺岡 浩史 | L11: 経営推進本部/広報部/サステナビリティ推進グループ/次世代育成支援チーム | M11: 町井 香織 | N11: 経営推進本部/広報部/企業広報グループ | O11: 古澤 祐幸 | T11: 経営推進本部/広報部/インターナルコミュニケーショングループ/インターナルコミュニケーションチーム
A12: キャリア関連 | C12: 大崎 敦士 | D12: ライブエクスペリエンス事業本部 | E12: 大崎敦士
A13: soup_curry | C13: 楠井 大地、神村 武 | D13: × | E13: 楠井大地 | F13: デジタルエンターテインメントオペレーションズ本部/モンスト運営部/ディレクターグループ | G13: 神村武 | H13: × | T13: ×
A14: 経営企画・法務共有 | C14: 泉望 | D14: コンプライアンス本部/法務部/オペレーショングループ | E14: 泉望 | T14: コンプライアンス本部/法務部/オペレーショングループ
A15: 影舞 | C15: 渡部 喜正 | D15: Vantageスタジオ/mixi事業部 | E15: 渡部喜正
A16: ノハナ採用 | B16: 退職 | C16: 大森 和悦、高杉 沙耶 | D16: 無 | E16: 大森和悦 | F16: 無 | G16: 高杉沙耶 | H16: × | T16: ノハナ事業部 | U16: 無 | V16: ノハナ事業部
A17: セキュリティ | C17: 亀山直生、村瀬龍馬 | D17: セキュリティ室(本部格) | E17: 亀山直生 | F17: × | G17: 村瀬龍馬 | H17: × | T17: セキュリティ室(本部格)
A18: 【機密】登用チャレンジ | C18: 卯木 源一 | D18: 人事本部/組織戦略部/横断HRBPグループ | E18: 卯木源一
A19: mr-scanner-output | C19: 長岡 輝 | D19: Vantageスタジオ/Romi事業部/UX企画グループ | E19: 長岡輝
A20: Bonfire | C20: 澤田祐希、 栗丸侑大、 吉田明広 | D20: 開発本部/たんぽぽ室/ブルーグループ | E20: 澤田祐希 | F20: × | G20: 栗丸侑大 | H20: × | I20: 吉田 明広 | J20: × | T20: 開発本部/たんぽぽ室/ブルーグループ
A21: Enishi | C21: 大崎 敦士 | D21: ライブエクスペリエンス事業本部 | E21: 大崎敦士
A22: mixiモールデータ | C22: 杉田 絵美 | D22: 開発本部/たんぽぽ室/Enablementグループ | E22: 杉田絵美
A23: 契約管理台帳 | C23: 小林 完爾 | D23: 上級執行役員 | E23: 小林完爾
A24: XFLAGアシスタント共有 | C24: 齋藤 敦子、宇佐美裕子、村上 由利奈、峯岸保栄 | D24: デジタルエンターテインメントオペレーションズ本部/モンスト運営部 | E24: 齋藤敦子
A25: ノハナサポート | C25: 牛田美穂 | D25: CS本部/CX部/Enhancementグループ/組織開発チーム | E25: 牛田美穂 | T25: CS本部/CX部/Enhancementグループ/組織開発チーム
A26: Creative | C26: 越智 純平 | D26: デザイン本部/動画クリエイティブ室 | E26: 越智純平
A27: mixiカンファレンス | C27: 岨中 健太 | D27: Vantageスタジオ/事業推進室 | E27: 岨中健太
A28: 知財運用支援 | C28: 村津 文武 | D28: コンプライアンス本部/知財室/商標・著作権グループ | E28: 村津文武
A29: 開発マネージャ共有 | B29: 退職 | C29: 福森 美貴 | D29: 人事部 | E29: 福森美貴 | F29: 人事部 | H29: × | T29: × | U29: 人事部 | V29: ×
A30: CONNECTIT_SF | B30: 退職 | C30: 洪 嘉優 | D30: 投資事業部 | E30: 洪嘉優 | F30: 投資事業部 | H30: × | T30: × | U30: 投資事業部 | V30: ×
A31: LE事業本部AM | C31: 長岡 輝 | D31: Vantageスタジオ/Romi事業部/UX企画グループ | E31: 長岡輝
A32: 経理・財務共有 | C32: 望月 大輔 | D32: コーポレートファイナンス本部/経理税務部 | E32: 望月大輔
A33: mb | B33: 退職 | C33: 竹田 広平 | D33: インキュベーション事業部 | E33: 竹田広平 | F33: インキュベーション事業部 | H33: × | T33: × | U33: インキュベーション事業部 | V33: ×
A34: MFプロジェクト | C34: 嵯峨 勇 | D34: はたらく環境推進本部/せいかつ環境室/せいかつ環境Aグループ | E34: 嵯峨勇
A35: 経理・労務共通 | C35: 中川 真紀子、 酒井 優、坂田 信隆a | D35: 人事本部/グループ会社サポート部 | E35: 中川真紀子
A36: SH人事・労務 | B36: 退職 | C36: 奥田 匡彦 | D36: 無し | E36: 奥田匡彦 | F36: 無し | H36: × | T36: × | U36: 無し | V36: ×
A37: mixipark | C37: 石井 公二 | D37: デジタルエンターテインメントパブリッシング本部 | E37: 石井公二
A38: fanfest2020 | C38: 山口 祥子 | D38: ライブエクスペリエンス事業本部/フットボール事業部/事業推進グループ | E38: 山口祥子
A39: ブラナイ | C39: 澁谷 高広 | D39: ソーシャルベッティング事業本部/TIPSTAR事業部/プロダクト戦略グループ/開発チーム | E39: 澁谷高広
A40: tech_data | C40: 横山 義之、曽我 雄二 | D40: デザイン本部 | E40: 横山義之
A41: 財務・労務共通 | B41: 退職 | C41: 菅原 亜弓、 中川 真紀子 | D41: 労務部 | E41: 菅原亜弓 | F41: 労務部 | G41: 中川真紀子 | H41: × | T41: × | U41: 労務部 | V41: ×
...

Sheet シート13
A1: アドテクスタジオ | B1: アドテクG
A2: アドテクスタジオ | B2: 企画G
A3: アドテクスタジオ | B3: 開発G
A4: アドテクスタジオ | B4: 室共有
A5: メディア事業本部 | B5: mixiゲーム部
A6: メディア事業本部 | B6: mixiサービス部
A7: メディア事業本部 | B7: 本部共有
A8: メディア事業本部 | B8: mixiコンテンツ部
A9: メディア事業本部 | B9: mixiシステム部
A10: Diverseスタジオ | B10: インドマーケット部
A11: Diverseスタジオ | B11: かいはつ室
A12: Diverseスタジオ | B12: ビジネス推進室
... A278: モンスト事業本部 | B278: 新規事業開発部
A280: 旧本部名 | B280: 旧部署名 | C280: ステータス | D280: 現在の本部/部署名 (予想) | E280: 部室長/室長名 (判明分)
A281: アドテクスタジオ | B281: アドテクG | C281: 廃止/再編 | D281: 開発本部 / デザイン本部 | E281: 不明
A282: アドテクスタジオ | B282: 企画G | C282: 廃止/再編 | D282: 開発本部 / デザイン本部 | E282: 不明
A283: アドテクスタジオ | B283: 開発G | C283: 廃止/再編 | D283: 開発本部 / デザイン本部 | E283: 不明
A284: アドテクスタジオ | B284: 室共有 | C284: 廃止/再編 | D284: - | E284: -
A285: メディア事業本部 | B285: mixiゲーム部 | C285: 廃止/再編 | D285: ゲーム事業部 | E285: 不明
A286: メディア事業本部 | B286: mixiサービス部 | C286: 廃止/再編 | D286: MIXI M事業部 | E286: 不明
A287: メディア事業本部 | B287: 本部共有 | C287: 廃止/再編 | D287: - | E287: -
A288: メディア事業本部 | B288: mixiコンテンツ部 | C288: 廃止/再編 | D288: MIXI M事業部 | E288: 不明
A289: メディア事業本部 | B289: mixiシステム部 | C289: 廃止/再編 | D289: MIXI M事業部 | E289: 不明
A290: Diverseスタジオ | B290: インドマーケット部 | C290: 廃止/分社化 | D290: 株式会社Diverse | E290: 不明
A291: Diverseスタジオ | B291: かいはつ室 | C291: 廃止/分社化 | D291: 株式会社Diverse | E291: 不明
... A558: モンスト事業本部 | B558: 新規事業開発部 | C558: 廃止/再編 | D558: モンスト事業部 | E558: 不明

Sheet 成形について
B3: 0File | C3: 不要そう
B4: 合致 | C4: 管理者が判明
B5: 不明 | C5: 管理者が不明
B6: 仮説 | C6: 組織変更により、現状の組織名と一致しないが、組織名より推測している | H6: 最後
B10: フォルダ名 | C10: 使用の有無 | D10: LastWrightTime | E10: ステータス | F10: 管理者 | G10: 管理者
C11: 0
C12: 300G
D14: ① | E14: ② | F14: ②
A15: 疑問 | G15: メモ
A16: 最初にもらったフォルダの数が合わない →0fileでもなく、最終更新日にも挙がっていないものが対象 | G16: 最終更新日は2020年以前のものをグレーアウト
G17: 最終更新日のシートにないものは、存在しない？
A18: 3年 42
A19: 6年 95 2025～2020
A21: データサイズはファイル数なのか？
A22: フォルダの容量は欲しい ｍｇ～のやつを1024で割って出す logのBytのものにする
A23: 最終更新日でバツがついているもの＝最初にもらったフォルダ一覧に存在しないフォルダは何？
A24: projectの容量を出す
A27: ・新規カラム（移行先）で1列Hot、coldのものを作成
A28: 3年以上更新していないもの＝cold
A30: Hot＝Googleドライブ
A31: cold＝AWS S3
A32: 不要
A33: 個人情報＝別テナント
... A36: 不要、自対応、hatakan依頼

Sheet ヒアリング先
A1: div 対象者 | B1: project 対象者
A2: =IFERROR(__xludf.DUMMYFUNCTION("UNIQUE(FLATTEN('（新）div'!L2:M379))"),"三島 圭介") -> 三島 圭介 | B2: =IFERROR(__xludf.DUMMYFUNCTION("UNIQUE(FLATTEN('（新）project_bk'!E5:E269,'（新）project_bk'!G5:G269,'（新）project_bk'!I5:I269,'（新）project_bk'!K5:K269,'（新）project_bk'!M5:M269,'（新）project_bk'!O5:O269,'（新）project_bk'!S5:S269))"),"山口祥子") -> 山口祥子
A3: =IFERROR(__xludf.DUMMYFUNCTION("""COMPUTED_VALUE"""),"松本 太寛") -> 松本 太寛 | B3: =IFERROR(__xludf.DUMMYFUNCTION("""COMPUTED_VALUE"""),"×") -> ×
A4: =IFERROR(__xludf.DUMMYFUNCTION("""COMPUTED_VALUE"""),"×") -> × | B4: =IFERROR(__xludf.DUMMYFUNCTION("""COMPUTED_VALUE"""),"佐藤僚") -> 佐藤僚
A5: =IFERROR(__xludf.DUMMYFUNCTION("""COMPUTED_VALUE"""),"薮崎 泰一") -> 薮崎 泰一 | B5: =IFERROR(__xludf.DUMMYFUNCTION("""COMPUTED_VALUE"""),"安井聡史") -> 安井聡史
A6: =IFERROR(__xludf.DUMMYFUNCTION("""COMPUTED_VALUE"""),"横山 義之") -> 横山 義之 | B6: =IFERROR(__xludf.DUMMYFUNCTION("""COMPUTED_VALUE"""),"山本陽司") -> 山本陽司
A7: =IFERROR(__xludf.DUMMYFUNCTION("""COMPUTED_VALUE"""),"野原 孝行") -> 野原 孝行 | B7: =IFERROR(__xludf.DUMMYFUNCTION("""COMPUTED_VALUE"""),"楠井大地") -> 楠井大地
A8: =IFERROR(__xludf.DUMMYFUNCTION("""COMPUTED_VALUE"""),"石井 公二") -> 石井 公二 | B8: =IFERROR(__xludf.DUMMYFUNCTION("""COMPUTED_VALUE"""),"佐藤貴亮") -> 佐藤貴亮
A9: =IFERROR(__xludf.DUMMYFUNCTION("""COMPUTED_VALUE"""),"青山 智史") -> 青山 智史 | B9: =IFERROR(__xludf.DUMMYFUNCTION("""COMPUTED_VALUE"""),"島村恒平") -> 島村恒平
A10: =IFERROR(__xludf.DUMMYFUNCTION("""COMPUTED_VALUE"""),"杉村 元規") -> 杉村 元規 | B10: =IFERROR(__xludf.DUMMYFUNCTION("""COMPUTED_VALUE"""),"大田由香") -> 大田由香
A11: =IFERROR(__xludf.DUMMYFUNCTION("""COMPUTED_VALUE"""),"坂田 信隆a") -> 坂田 信隆a | B11: =IFERROR(__xludf.DUMMYFUNCTION("""COMPUTED_VALUE"""),"杉田絵美") -> 杉田絵美
A12: =IFERROR(__xludf.DUMMYFUNCTION("""COMPUTED_VALUE"""),"中川 真紀子") -> 中川 真紀子 | B12: =IFERROR(__xludf.DUMMYFUNCTION("""COMPUTED_VALUE"""),"熊本満里奈") -> 熊本満里奈
A13: =IFERROR(__xludf.DUMMYFUNCTION("""COMPUTED_VALUE"""),"加藤 里紗") -> 加藤 里紗 | B13: =IFERROR(__xludf.DUMMYFUNCTION("""COMPUTED_VALUE"""),"長岡輝") -> 長岡輝
A14: =IFERROR(__xludf.DUMMYFUNCTION("""COMPUTED_VALUE"""),"山本 陽司") -> 山本 陽司 | B14: =IFERROR(__xludf.DUMMYFUNCTION("""COMPUTED_VALUE"""),"安田勇大") -> 安田勇大
A15: =IFERROR(__xludf.DUMMYFUNCTION("""COMPUTED_VALUE"""),"柳本 修平") -> 柳本 修平 | B15: =IFERROR(__xludf.DUMMYFUNCTION("""COMPUTED_VALUE"""),"木村俊也") -> 木村俊也
A16: =IFERROR(__xludf.DUMMYFUNCTION("""COMPUTED_VALUE"""),"井上 慎也") -> 井上 慎也 | B16: =IFERROR(__xludf.DUMMYFUNCTION("""COMPUTED_VALUE"""),"向中野智志") -> 向中野智志
A17: =IFERROR(__xludf.DUMMYFUNCTION("""COMPUTED_VALUE"""),"望月 大輔") -> 望月 大輔 | B17: =IFERROR(__xludf.DUMMYFUNCTION("""COMPUTED_VALUE"""),"菅原亜弓") -> 菅原亜弓
A18: =IFERROR(__xludf.DUMMYFUNCTION("""COMPUTED_VALUE"""),"荒木 豪司") -> 荒木 豪司 | B18: =IFERROR(__xludf.DUMMYFUNCTION("""COMPUTED_VALUE"""),"宇高邦弘") -> 宇高邦弘
A19: =IFERROR(__xludf.DUMMYFUNCTION("""COMPUTED_VALUE"""),"大場 大史") -> 大場 大史 | B19: =IFERROR(__xludf.DUMMYFUNCTION("""COMPUTED_VALUE"""),"西澤明日香") -> 西澤明日香
A20: =IFERROR(__xludf.DUMMYFUNCTION("""COMPUTED_VALUE"""),"宇田川 浩彦") -> 宇田川 浩彦 | B20: =IFERROR(__xludf.DUMMYFUNCTION("""COMPUTED_VALUE"""),"岨中健太") -> 岨中健太
A21: =IFERROR(__xludf.DUMMYFUNCTION("""COMPUTED_VALUE"""),"志々目 孝広") -> 志々目 孝広 | B21: =IFERROR(__xludf.DUMMYFUNCTION("""COMPUTED_VALUE"""),"横山義之") -> 横山義之
A22: =IFERROR(__xludf.DUMMYFUNCTION("""COMPUTED_VALUE"""),"谷 賢史") -> 谷 賢史 | B22: =IFERROR(__xludf.DUMMYFUNCTION("""COMPUTED_VALUE"""),"早川泰彦") -> 早川泰彦
A23: =IFERROR(__xludf.DUMMYFUNCTION("""COMPUTED_VALUE"""),"安井 聡史") -> 安井 聡史 | B23: =IFERROR(__xludf.DUMMYFUNCTION("""COMPUTED_VALUE"""),"小野里浩司") -> 小野里浩司
A24: =IFERROR(__xludf.DUMMYFUNCTION("""COMPUTED_VALUE"""),"越智 純平") -> 越智 純平 | B24: =IFERROR(__xludf.DUMMYFUNCTION("""COMPUTED_VALUE"""),"寺谷祐樹") -> 寺谷祐樹
A25: =IFERROR(__xludf.DUMMYFUNCTION("""COMPUTED_VALUE"""),"大槻 一彦") -> 大槻 一彦 | B25: =IFERROR(__xludf.DUMMYFUNCTION("""COMPUTED_VALUE"""),"櫻井謙士") -> 櫻井謙士
A26: =IFERROR(__xludf.DUMMYFUNCTION("""COMPUTED_VALUE"""),"髙橋 勇太") -> 髙橋 勇太 | B26: =IFERROR(__xludf.DUMMYFUNCTION("""COMPUTED_VALUE"""),"三嶋佳織") -> 三嶋佳織
A27: =IFERROR(__xludf.DUMMYFUNCTION("""COMPUTED_VALUE"""),"岡本 勇太") -> 岡本 勇太 | B27: =IFERROR(__xludf.DUMMYFUNCTION("""COMPUTED_VALUE"""),"新和博") -> 新和博
A28: =IFERROR(__xludf.DUMMYFUNCTION("""COMPUTED_VALUE"""),"吉永 英恵") -> 吉永 英恵 | B28: =IFERROR(__xludf.DUMMYFUNCTION("""COMPUTED_VALUE"""),"加奈山怜") -> 加奈山怜
A29: =IFERROR(__xludf.DUMMYFUNCTION("""COMPUTED_VALUE"""),"照内 大丈") -> 照内 大丈 | B29: =IFERROR(__xludf.DUMMYFUNCTION("""COMPUTED_VALUE"""),"小林誠") -> 小林誠
A30: =IFERROR(__xludf.DUMMYFUNCTION("""COMPUTED_VALUE"""),"砂村 哲平") -> 砂村 哲平 | B30: =IFERROR(__xludf.DUMMYFUNCTION("""COMPUTED_VALUE"""),"玉井賀子") -> 玉井賀子
A31: =IFERROR(__xludf.DUMMYFUNCTION("""COMPUTED_VALUE"""),"吉野 純平") -> 吉野 純平 | B31: =IFERROR(__xludf.DUMMYFUNCTION("""COMPUTED_VALUE"""),"加藤佳代") -> 加藤佳代
B32: =IFERROR(__xludf.DUMMYFUNCTION("""COMPUTED_VALUE"""),"塚田亜希子") -> 塚田亜希子
A33: =IFERROR(__xludf.DUMMYFUNCTION("""COMPUTED_VALUE"""),"小林 家光") -> 小林 家光 | B33: =IFERROR(__xludf.DUMMYFUNCTION("""COMPUTED_VALUE"""),"木村真") -> 木村真
A34: =IFERROR(__xludf.DUMMYFUNCTION("""COMPUTED_VALUE"""),"大崎 敦士") -> 大崎 敦士 | B34: =IFERROR(__xludf.DUMMYFUNCTION("""COMPUTED_VALUE"""),"小林完爾") -> 小林完爾
A35: =IFERROR(__xludf.DUMMYFUNCTION("""COMPUTED_VALUE"""),"川岸 滋也") -> 川岸 滋也 | B35: =IFERROR(__xludf.DUMMYFUNCTION("""COMPUTED_VALUE"""),"石井瞬") -> 石井瞬
A36: =IFERROR(__xludf.DUMMYFUNCTION("""COMPUTED_VALUE"""),"長井 一悟") -> 長井 一悟 | B36: =IFERROR(__xludf.DUMMYFUNCTION("""COMPUTED_VALUE"""),"嵯峨勇") -> 嵯峨勇
A37: =IFERROR(__xludf.DUMMYFUNCTION("""COMPUTED_VALUE"""),"石田 哲久") -> 石田 哲久 | B37: =IFERROR(__xludf.DUMMYFUNCTION("""COMPUTED_VALUE"""),"小林一希") -> 小林一希
A38: =IFERROR(__xludf.DUMMYFUNCTION("""COMPUTED_VALUE"""),"菊池 翔平") -> 菊池 翔平 | B38: =IFERROR(__xludf.DUMMYFUNCTION("""COMPUTED_VALUE"""),"加藤徳英") -> 加藤徳英
A39: =IFERROR(__xludf.DUMMYFUNCTION("""COMPUTED_VALUE"""),"岨中 健太") -> 岨中 健太 | B39: =IFERROR(__xludf.DUMMYFUNCTION("""COMPUTED_VALUE"""),"渡部喜正") -> 渡部喜正
A40: =IFERROR(__xludf.DUMMYFUNCTION("""COMPUTED_VALUE"""),"佐藤 太一") -> 佐藤 太一 | B40: =IFERROR(__xludf.DUMMYFUNCTION("""COMPUTED_VALUE"""),"譚正文") -> 譚正文
...

Sheet div回答シートURL一覧
A1: 確認先氏名 | B1: SpreadsheetのURL | C1: 件数
A2: 松本 太寛 | B2: https://docs.google.com/spreadsheets/d/1nwdJm_GfdQ1mcJ2ioPHTpKfA3jFL6Blrp61iAHbQq-c/edit | C2: 3
A3: 薮崎 泰一 | B3: https://docs.google.com/spreadsheets/d/1UTgk-a5mWckfGHmzn_hf00PInd0E0gt1VwiCmDn6Uuc/edit | C3: 6
A4: 横山 義之 | B4: https://docs.google.com/spreadsheets/d/1_3QaojSh1OFHSnWqh0FLKul75t-aTpo21dF3aIh9tY8/edit | C4: 12
A5: 野原 孝行 | B5: https://docs.google.com/spreadsheets/d/1gK_f1y2An-sgoKBeFe6btEDLSqxQ_2RZg4KRoRMXbqw/edit | C5: 1
A6: div不明 | B6: https://docs.google.com/spreadsheets/d/1dODR5r7IHQs_bBrnoAAFSNDXLRruZN-RMagTfP3qFLk/edit | C6: 39
A7: 三島 圭介 | B7: https://docs.google.com/spreadsheets/d/1cLWKrRc_FAfJGmNFDGTAwVG_SLS1TbFIyBMUouoody0/edit | C7: 27
A8: 坂田 信隆a | B8: https://docs.google.com/spreadsheets/d/19DE5eeNf5sI0lMc68eIG_RaDD1__D-CDnCY2D-hJQOI/edit | C8: 1
A9: 杉村 元規 | B9: https://docs.google.com/spreadsheets/d/1fuiSwtPkqEMOKFjLpSFKPv3fXVsy__MDJUzC_nUk23A/edit | C9: 12
A10: 加藤 里紗 | B10: https://docs.google.com/spreadsheets/d/1w8zBslU49e2rqaezMVBA-oZv6Kg9-sw_uL14ui46wck/edit | C10: 1
A11: 山本 陽司 | B11: https://docs.google.com/spreadsheets/d/1za6ZHPnww1HLwYW674Eds8fg-tIe40_e4AmQHlL0bus/edit | C11: 1
A12: 井上 慎也 | B12: https://docs.google.com/spreadsheets/d/1uxA1q_ItA1ql8CLzdvoi-bSamIO6-cscLDpaMms0Tts/edit | C12: 1
A13: 志々目 孝広 | B13: https://docs.google.com/spreadsheets/d/1ACC2Z-s-EYf4tJg_Vwfqmwgu7nypM_daoXlVfG60ybM/edit | C13: 5
... A44: div確認先を除外 | B44: https://docs.google.com/spreadsheets/d/1DwpFEZ4f8P6Obxtdd6OB5tjjtth5liWQaXvwvNz6r-8/edit | C44: 286

Sheet project回答シートURL一覧
A1: 確認先氏名 | B1: SpreadsheetのURL | C1: 件数
A2: project不明 | B2: https://docs.google.com/spreadsheets/d/1CcjRFBFG7iOiqTD2fTfX3OMgml3WL0QjCSl6NYf1H7Y/edit | C2: 324

Sheet （新）div
A1: div 1階層目フォルダ | B1: div 2階層目フォルダ | C1: ステータス | D1: フォルダ数 | E1: ファイル数 | F1: データ容量GB） | G1: 最終更新日 | H1: 移行先 | I1: 移行方法 | J1: 本部予想 | K1: 部室予想 | L1: 確認先（本部長） | M1: 確認先（部室長） | N1: 現状予測 | O1: 仮説 | P1: LastEditDate
A2: アドテクスタジオ | B2: アドテクG | C2: 0file | D2: =IFERROR(__xludf.DUMMYFUNCTION("XLOOKUP(JOIN(""/"",$A2:$B2),'source merged_div_data'!$A:$A,'source merged_div_data'!B:B)"),4.0) -> 4 | E2: =IFERROR(__xludf.DUMMYFUNCTION("XLOOKUP(JOIN(""/"",$A2:$B2),'source merged_div_data'!$A:$A,'source merged_div_data'!C:C)"),0.0) -> 0 | F2: {=IFERROR( IFS( XLOOKUP(TEXTJOIN("/", TRUE, $A2:$B2), 'source merged_div_data'!$A:$A, 'source merged_div_data'!F:F) < 1024, XLOOKUP(TEXTJOIN("/", TRUE, $A2:$B2), 'source merged_div_data'!$A:$A, 'source merged_div_data'!F:F) & " B", XLOOKUP(TEXTJOIN("/", TRUE, $A2:$B2), 'source merged_div_data'!$A:$A, 'source merged_div_data'!F:F) < 1048576, ROUND(XLOOKUP(TEXTJOIN("/", TRUE, $A2:$B2), 'source merged_div_data'!$A:$A, 'source merged_div_data'!F:F)/1024, 2) & " KB", XLOOKUP(TEXTJOIN("/", TRUE, $A2:$B2), 'source merged_div_data'!$A:$A, 'source merged_div_data'!F:F) < 1073741824, ROUND(XLOOKUP(TEXTJOIN("/", TRUE, $A2:$B2), 'source merged_div_data'!$A:$A, 'source merged_div_data'!F:F)/1048576, 2) & " MB", TRUE, ROUND(XLOOKUP(TEXTJOIN("/", TRUE, $A2:$B2), 'source merged_div_data'!$A:$A, 'source merged_div_data'!F:F)/1073741824, 2) & " GB" ), "×" )} -> 86 B | G2: × | J2: デジタルエンターテインメントオペレーションズ本部 | K2: 宣伝部 | L2: 三島 圭介 | M2: 松本 太寛 | N2: 廃止/再編 | O2: 開発本部 / デザイン本部 | P2: =IFERROR(__xludf.DUMMYFUNCTION("XLOOKUP(JOIN(""/"",$A2:$B2),'source isilon_divまとめ'!$A:$A,'source isilon_divまとめ'!$D:$D,XLOOKUP(JOIN(""\"",$A2:$B2),'source NetApp-file-sv01-div'!A:A,TEXT('source NetApp-file-sv01-div'!C:C,""yyyy/mm/dd"")))"),"#N/A") -> #N/A
A3: アドテクスタジオ | B3: 企画G | C3: 0file | D3: =IFERROR(__xludf.DUMMYFUNCTION("XLOOKUP(JOIN(""/"",$A3:$B3),'source merged_div_data'!$A:$A,'source merged_div_data'!B:B)"),3.0) -> 3 | E3: =IFERROR(__xludf.DUMMYFUNCTION("XLOOKUP(JOIN(""/"",$A3:$B3),'source merged_div_data'!$A:$A,'source merged_div_data'!C:C)"),0.0) -> 0 | F3: {=IFERROR( IFS( XLOOKUP(TEXTJOIN("/", TRUE, $A3:$B3), 'source merged_div_data'!$A:$A, 'source merged_div_data'!F:F) < 1024, XLOOKUP(TEXTJOIN("/", TRUE, $A3:$B3), 'source merged_div_data'!$A:$A, 'source merged_div_data'!F:F) & " B", XLOOKUP(TEXTJOIN("/", TRUE, $A3:$B3), 'source merged_div_data'!$A:$A, 'source merged_div_data'!F:F) < 1048576, ROUND(XLOOKUP(TEXTJOIN("/", TRUE, $A3:$B3), 'source merged_div_data'!$A:$A, 'source merged_div_data'!F:F)/1024, 2) & " KB", XLOOKUP(TEXTJOIN("/", TRUE, $A3:$B3), 'source merged_div_data'!$A:$A, 'source merged_div_data'!F:F) < 1073741824, ROUND(XLOOKUP(TEXTJOIN("/", TRUE, $A3:$B3), 'source merged_div_data'!$A:$A, 'source merged_div_data'!F:F)/1048576, 2) & " MB", TRUE, ROUND(XLOOKUP(TEXTJOIN("/", TRUE, $A3:$B3), 'source merged_div_data'!$A:$A, 'source merged_div_data'!F:F)/1073741824, 2) & " GB" ), "×" )} -> 61 B | G3: × | J3: デジタルエンターテインメントオペレーションズ本部 | K3: 宣伝部 | L3: 三島 圭介 | M3: 松本 太寛 | N3: 廃止/再編 | O3: 開発本部 / デザイン本部 | P3: =IFERROR(__xludf.DUMMYFUNCTION("XLOOKUP(JOIN(""/"",$A3:$B3),'source isilon_divまとめ'!$A:$A,'source isilon_divまとめ'!$D:$D,XLOOKUP(JOIN(""\"",$A3:$B3),'source NetApp-file-sv01-div'!A:A,TEXT('source NetApp-file-sv01-div'!C:C,""yyyy/mm/dd"")))"),"#N/A") -> #N/A
A4: アドテクスタジオ | B4: 開発G | C4: 0file | D4: =IFERROR(__xludf.DUMMYFUNCTION("XLOOKUP(JOIN(""/"",$A4:$B4),'source merged_div_data'!$A:$A,'source merged_div_data'!B:B)"),3.0) -> 3 | E4: =IFERROR(__xludf.DUMMYFUNCTION("XLOOKUP(JOIN(""/"",$A4:$B4),'source merged_div_data'!$A:$A,'source merged_div_data'!C:C)"),0.0) -> 0 | F4: {=IFERROR( IFS( XLOOKUP(TEXTJOIN("/", TRUE, $A4:$B4), 'source merged_div_data'!$A:$A, 'source merged_div_data'!F:F) < 1024, XLOOKUP(TEXTJOIN("/", TRUE, $A4:$B4), 'source merged_div_data'!$A:$A, 'source merged_div_data'!F:F) & " B", XLOOKUP(TEXTJOIN("/", TRUE, $A4:$B4), 'source merged_div_data'!$A:$A, 'source merged_div_data'!F:F) < 1048576, ROUND(XLOOKUP(TEXTJOIN("/", TRUE, $A4:$B4), 'source merged_div_data'!$A:$A, 'source merged_div_data'!F:F)/1024, 2) & " KB", XLOOKUP(TEXTJOIN("/", TRUE, $A4:$B4), 'source merged_div_data'!$A:$A, 'source merged_div_data'!F:F) < 1073741824, ROUND(XLOOKUP(TEXTJOIN("/", TRUE, $A4:$B4), 'source merged_div_data'!$A:$A, 'source merged_div_data'!F:F)/1048576, 2) & " MB", TRUE, ROUND(XLOOKUP(TEXTJOIN("/", TRUE, $A4:$B4), 'source merged_div_data'!$A:$A, 'source merged_div_data'!F:F)/1073741824, 2) & " GB" ), "×" )} -> 61 B | G4: × | J4: デジタルエンターテインメントオペレーションズ本部 | K4: 宣伝部 | L4: 三島 圭介 | M4: 松本 太寛 | N4: 廃止/再編 | O4: 開発本部 / デザイン本部 | P4: =IFERROR(__xludf.DUMMYFUNCTION("XLOOKUP(JOIN(""/"",$A4:$B4),'source isilon_divまとめ'!$A:$A,'source isilon_divまとめ'!$D:$D,XLOOKUP(JOIN(""\"",$A4:$B4),'source NetApp-file-sv01-div'!A:A,TEXT('source NetApp-file-sv01-div'!C:C,""yyyy/mm/dd"")))"),"#N/A") -> #N/A
A5: アドテクスタジオ | B5: 室共有 | C5: 0file | D5: =IFERROR(__xludf.DUMMYFUNCTION("XLOOKUP(JOIN(""/"",$A5:$B5),'source merged_div_data'!$A:$A,'source merged_div_data'!B:B)"),2.0) -> 2 | E5: =IFERROR(__xludf.DUMMYFUNCTION("XLOOKUP(JOIN(""/"",$A5:$B5),'source merged_div_data'!$A:$A,'source merged_div_data'!C:C)"),0.0) -> 0 | F5: {=IFERROR( IFS( XLOOKUP(TEXTJOIN("/", TRUE, $A5:$B5), 'source merged_div_data'!$A:$A, 'source merged_div_data'!F:F) < 1024, XLOOKUP(TEXTJOIN("/", TRUE, $A5:$B5), 'source merged_div_data'!$A:$A, 'source merged_div_data'!F:F) & " B", XLOOKUP(TEXTJOIN("/", TRUE, $A5:$B5), 'source merged_div_data'!$A:$A, 'source merged_div_data'!F:F) < 1048576, ROUND(XLOOKUP(TEXTJOIN("/", TRUE, $A5:$B5), 'source merged_div_data'!$A:$A, 'source merged_div_data'!F:F)/1024, 2) & " KB", XLOOKUP(TEXTJOIN("/", TRUE, $A5:$B5), 'source merged_div_data'!$A:$A, 'source merged_div_data'!F:F) < 1073741824, ROUND(XLOOKUP(TEXTJOIN("/", TRUE, $A5:$B5), 'source merged_div_data'!$A:$A, 'source merged_div_data'!F:F)/1048576, 2) & " MB", TRUE, ROUND(XLOOKUP(TEXTJOIN("/", TRUE, $A5:$B5), 'source merged_div_data'!$A:$A, 'source merged_div_data'!F:F)/1073741824, 2) & " GB" ), "×" )} -> 39 B | G5: × | J5: デジタルエンターテインメントオペレーションズ本部 | K5: 宣伝部 | L5: 三島 圭介 | M5: 松本 太寛 | N5: 廃止/再編 | O5: - | P5: =IFERROR(__xludf.DUMMYFUNCTION("XLOOKUP(JOIN(""/"",$A5:$B5),'source isilon_divまとめ'!$A:$A,'source isilon_divまとめ'!$D:$D,XLOOKUP(JOIN(""\"",$A5:$B5),'source NetApp-file-sv01-div'!A:A,TEXT('source NetApp-file-sv01-div'!C:C,""yyyy/mm/dd"")))"),"#N/A") -> #N/A
A6: メディア事業本部 | B6: mixiゲーム部 | C6: 仮説 | D6: =IFERROR(__xludf.DUMMYFUNCTION("XLOOKUP(JOIN(""/"",$A6:$B6),'source merged_div_data'!$A:$A,'source merged_div_data'!B:B)"),32.0) -> 32 | E6: =IFERROR(__xludf.DUMMYFUNCTION("XLOOKUP(JOIN(""/"",$A6:$B6),'source merged_div_data'!$A:$A,'source merged_div_data'!C:C)"),17.0) -> 17 | F6: {=IFERROR( IFS( XLOOKUP(TEXTJOIN("/", TRUE, $A6:$B6), 'source merged_div_data'!$A:$A, 'source merged_div_data'!F:F) < 1024, XLOOKUP(TEXTJOIN("/", TRUE, $A6:$B6), 'source merged_div_data'!$A:$A, 'source merged_div_data'!F:F) & " B", XLOOKUP(TEXTJOIN("/", TRUE, $A6:$B6), 'source merged_div_data'!$A:$A, 'source merged_div_data'!F:F) < 1048576, ROUND(XLOOKUP(TEXTJOIN("/", TRUE, $A6:$B6), 'source merged_div_data'!$A:$A, 'source merged_div_data'!F:F)/1024, 2) & " KB", XLOOKUP(TEXTJOIN("/", TRUE, $A6:$B6), 'source merged_div_data'!$A:$A, 'source merged_div_data'!F:F) < 1073741824, ROUND(XLOOKUP(TEXTJOIN("/", TRUE, $A6:$B6), 'source merged_div_data'!$A:$A, 'source merged_div_data'!F:F)/1048576, 2) & " MB", TRUE, ROUND(XLOOKUP(TEXTJOIN("/", TRUE, $A6:$B6), 'source merged_div_data'!$A:$A, 'source merged_div_data'!F:F)/1073741824, 2) & " GB" ), "×" )} -> 19.25 MB | G6: 2016/04/20 | H6: AWS S3 | J6: デジタルエンターテインメントオペレーションズ本部 | K6: 宣伝部 | L6: 三島 圭介 | M6: 松本 太寛 | N6: 廃止/再編 | O6: ゲーム事業部 | P6: =IFERROR(__xludf.DUMMYFUNCTION("XLOOKUP(JOIN(""/"",$A6:$B6),'source isilon_divまとめ'!$A:$A,'source isilon_divまとめ'!$D:$D,XLOOKUP(JOIN(""\"",$A6:$B6),'source NetApp-file-sv01-div'!A:A,TEXT('source NetApp-file-sv01-div'!C:C,""yyyy/mm/dd"")))"),"2016/04/20") -> 2016/04/20
A7: メディア事業本部 | B7: mixiサービス部 | C7: 仮説 | D7: =IFERROR(__xludf.DUMMYFUNCTION("XLOOKUP(JOIN(""/"",$A7:$B7),'source merged_div_data'!$A:$A,'source merged_div_data'!B:B)"),55.0) -> 55 | E7: =IFERROR(__xludf.DUMMYFUNCTION("XLOOKUP(JOIN(""/"",$A7:$B7),'source merged_div_data'!$A:$A,'source merged_div_data'!C:C)"),53.0) -> 53 | F7: {=IFERROR( IFS( XLOOKUP(TEXTJOIN("/", TRUE, $A7:$B7), 'source merged_div_data'!$A:$A, 'source merged_div_data'!F:F) < 1024, XLOOKUP(TEXTJOIN("/", TRUE, $A7:$B7), 'source merged_div_data'!$A:$A, 'source merged_div_data'!F:F) & " B", XLOOKUP(TEXTJOIN("/", TRUE, $A7:$B7), 'source merged_div_data'!$A:$A, 'source merged_div_data'!F:F) < 1048576, ROUND(XLOOKUP(TEXTJOIN("/", TRUE, $A7:$B7), 'source merged_div_data'!$A:$A, 'source merged_div_data'!F:F)/1024, 2) & " KB", XLOOKUP(TEXTJOIN("/", TRUE, $A7:$B7), 'source merged_div_data'!$A:$A, 'source merged_div_data'!F:F) < 1073741824, ROUND(XLOOKUP(TEXTJOIN("/", TRUE, $A7:$B7), 'source merged_div_data'!$A:$A, 'source merged_div_data'!F:F)/1048576, 2) & " MB", TRUE, ROUND(XLOOKUP(TEXTJOIN("/", TRUE, $A7:$B7), 'source merged_div_data'!$A:$A, 'source merged_div_data'!F:F)/1073741824, 2) & " GB" ), "×" )} -> 8.61 MB | G7: 2016/03/04 | H7: AWS S3 | J7: 開発本部 | K7: MIXI M 事業部 | L7: × | M7: 薮崎 泰一 | N7: 廃止/再編 | O7: MIXI M事業部 | P7: =IFERROR(__xludf.DUMMYFUNCTION("XLOOKUP(JOIN(""/"",$A7:$B7),'source isilon_divまとめ'!$A:$A,'source isilon_divまとめ'!$D:$D,XLOOKUP(JOIN(""\"",$A7:$B7),'source NetApp-file-sv01-div'!A:A,TEXT('source NetApp-file-sv01-div'!C:C,""yyyy/mm/dd"")))"),"2016/03/04") -> 2016/03/04
A8: メディア事業本部 | B8: 本部共有 | C8: 不明 | D8: =IFERROR(__xludf.DUMMYFUNCTION("XLOOKUP(JOIN(""/"",$A8:$B8),'source merged_div_data'!$A:$A,'source merged_div_data'!B:B)"),1345.0) -> 1345 | E8: =IFERROR(__xludf.DUMMYFUNCTION("XLOOKUP(JOIN(""/"",$A8:$B8),'source merged_div_data'!$A:$A,'source merged_div_data'!C:C)"),9883.0) -> 9883 | F8: {=IFERROR( IFS( XLOOKUP(TEXTJOIN("/", TRUE, $A8:$B8), 'source merged_div_data'!$A:$A, 'source merged_div_data'!F:F) < 1024, XLOOKUP(TEXTJOIN("/", TRUE, $A8:$B8), 'source merged_div_data'!$A:$A, 'source merged_div_data'!F:F) & " B", XLOOKUP(TEXTJOIN("/", TRUE, $A8:$B8), 'source merged_div_data'!$A:$A, 'source merged_div_data'!F:F) < 1048576, ROUND(XLOOKUP(TEXTJOIN("/", TRUE, $A8:$B8), 'source merged_div_data'!$A:$A, 'source merged_div_data'!F:F)/1024, 2) & " KB", XLOOKUP(TEXTJOIN("/", TRUE, $A8:$B8), 'source merged_div_data'!$A:$A, 'source merged_div_data'!F:F) < 1073741824, ROUND(XLOOKUP(TEXTJOIN("/", TRUE, $A8:$B8), 'source merged_div_data'!$A:$A, 'source merged_div_data'!F:F)/1048576, 2) & " MB", TRUE, ROUND(XLOOKUP(TEXTJOIN("/", TRUE, $A8:$B8), 'source merged_div_data'!$A:$A, 'source merged_div_data'!F:F)/1073741824, 2) & " GB" ), "×" )} -> 7.72 GB | G8: 2022/04/16 | H8: AWS S3 | J8: デザイン本部 | L8: 横山 義之 | M8: × | N8: 廃止/再編 | O8: - | P8: =IFERROR(__xludf.DUMMYFUNCTION("XLOOKUP(JOIN(""/"",$A8:$B8),'source isilon_divまとめ'!$A:$A,'source isilon_divまとめ'!$D:$D,XLOOKUP(JOIN(""\"",$A8:$B8),'source NetApp-file-sv01-div'!A:A,TEXT('source NetApp-file-sv01-div'!C:C,""yyyy/mm/dd"")))"),"2022/04/16") -> 2022/04/16
A9: メディア事業本部 | B9: mixiコンテンツ部 | C9: 0file | D9: =IFERROR(__xludf.DUMMYFUNCTION("XLOOKUP(JOIN(""/"",$A9:$B9),'source merged_div_data'!$A:$A,'source merged_div_data'!B:B)"),29.0) -> 29 | E9: =IFERROR(__xludf.DUMMYFUNCTION("XLOOKUP(JOIN(""/"",$A9:$B9),'source merged_div_data'!$A:$A,'source merged_div_data'!C:C)"),0.0) -> 0 | F9: {=IFERROR( IFS( XLOOKUP(TEXTJOIN("/", TRUE, $A9:$B9), 'source merged_div_data'!$A:$A, 'source merged_div_data'!F:F) < 1024, XLOOKUP(TEXTJOIN("/", TRUE, $A9:$B9), 'source merged_div_data'!$A:$A, 'source merged_div_data'!F:F) & " B", XLOOKUP(TEXTJOIN("/", TRUE, $A9:$B9), 'source merged_div_data'!$A:$A, 'source merged_div_data'!F:F) < 1048576, ROUND(XLOOKUP(TEXTJOIN("/", TRUE, $A9:$B9), 'source merged_div_data'!$A:$A, 'source merged_div_data'!F:F)/1024, 2) & " KB", XLOOKUP(TEXTJOIN("/", TRUE, $A9:$B9), 'source merged_div_data'!$A:$A, 'source merged_div_data'!F:F) < 1073741824, ROUND(XLOOKUP(TEXTJOIN("/", TRUE, $A9:$B9), 'source merged_div_data'!$A:$A, 'source merged_div_data'!F:F)/1048576, 2) & " MB", TRUE, ROUND(XLOOKUP(TEXTJOIN("/", TRUE, $A9:$B9), 'source merged_div_data'!$A:$A, 'source merged_div_data'!F:F)/1073741824, 2) & " GB" ), "×" )} -> 868 B | G9: × | J9: 開発本部 | K9: MIXI M 事業部 | L9: × | M9: 薮崎 泰一 | N9: 廃止/再編 | O9: MIXI M事業部 | P9: =IFERROR(__xludf.DUMMYFUNCTION("XLOOKUP(JOIN(""/"",$A9:$B9),'source isilon_divまとめ'!$A:$A,'source isilon_divまとめ'!$D:$D,XLOOKUP(JOIN(""\"",$A9:$B9),'source NetApp-file-sv01-div'!A:A,TEXT('source NetApp-file-sv01-div'!C:C,""yyyy/mm/dd"")))"),"#N/A") -> #N/A
A10: メディア事業本部 | B10: mixiシステム部 | C10: 仮説 | D10: =IFERROR(__xludf.DUMMYFUNCTION("XLOOKUP(JOIN(""/"",$A10:$B10),'source merged_div_data'!$A:$A,'source merged_div_data'!B:B)"),19.0) -> 19 | E10: =IFERROR(__xludf.DUMMYFUNCTION("XLOOKUP(JOIN(""/"",$A10:$B10),'source merged_div_data'!$A:$A,'source merged_div_data'!C:C)"),19.0) -> 19 | F10: {=IFERROR( IFS( XLOOKUP(TEXTJOIN("/", TRUE, $A10:$B10), 'source merged_div_data'!$A:$A, 'source merged_div_data'!F:F) < 1024, XLOOKUP(TEXTJOIN("/", TRUE, $A10:$B10), 'source merged_div_data'!$A:$A, 'source merged_div_data'!F:F) & " B", XLOOKUP(TEXTJOIN("/", TRUE, $A10:$B10), 'source merged_div_data'!$A:$A, 'source merged_div_data'!F:F) < 1048576, ROUND(XLOOKUP(TEXTJOIN("/", TRUE, $A10:$B10), 'source merged_div_data'!$A:$A, 'source merged_div_data'!F:F)/1024, 2) & " KB", XLOOKUP(TEXTJOIN("/", TRUE, $A10:$B10), 'source merged_div_data'!$A:$A, 'source merged_div_data'!F:F) < 1073741824, ROUND(XLOOKUP(TEXTJOIN("/", TRUE, $A10:$B10), 'source merged_div_data'!$A:$A, 'source merged_div_data'!F:F)/1048576, 2) & " MB", TRUE, ROUND(XLOOKUP(TEXTJOIN("/", TRUE, $A10:$B10), 'source merged_div_data'!$A:$A, 'source merged_div_data'!F:F)/1073741824, 2) & " GB" ), "×" )} -> 29.29 MB | G10: 2016/05/19 | H10: AWS S3 | J10: 開発本部 | K10: MIXI M 事業部 | L10: × | M10: 薮崎 泰一 | N10: 廃止/再編 | O10: MIXI M事業部 | P10: =IFERROR(__xludf.DUMMYFUNCTION("XLOOKUP(JOIN(""/"",$A10:$B10),'source isilon_divまとめ'!$A:$A,'source isilon_divまとめ'!$D:$D,XLOOKUP(JOIN(""\"",$A10:$B10),'source NetApp-file-sv01-div'!A:A,TEXT('source NetApp-file-sv01-div'!C:C,""yyyy/mm/dd"")))"),"2016/05/19") -> 2016/05/19
A11: Diverseスタジオ | B11: インドマーケット部 | C11: 不明 | D11: =IFERROR(__xludf.DUMMYFUNCTION("XLOOKUP(JOIN(""/"",$A11:$B11),'source merged_div_data'!$A:$A,'source merged_div_data'!B:B)"),4.0) -> 4 | E11: =IFERROR(__xludf.DUMMYFUNCTION("XLOOKUP(JOIN(""/"",$A11:$B11),'source merged_div_data'!$A:$A,'source merged_div_data'!C:C)"),0.0) -> 0 | F11: {=IFERROR( IFS( XLOOKUP(TEXTJOIN("/", TRUE, $A11:$B11), 'source merged_div_data'!$A:$A, 'source merged_div_data'!F:F) < 1024, XLOOKUP(TEXTJOIN("/", TRUE, $A11:$B11), 'source merged_div_data'!$A:$A, 'source merged_div_data'!F:F) & " B", XLOOKUP(TEXTJOIN("/", TRUE, $A11:$B11), 'source merged_div_data'!$A:$A, 'source merged_div_data'!F:F) < 1048576, ROUND(XLOOKUP(TEXTJOIN("/", TRUE, $A11:$B11), 'source merged_div_data'!$A:$A, 'source merged_div_data'!F:F)/1024, 2) & " KB", XLOOKUP(TEXTJOIN("/", TRUE, $A11:$B11), 'source merged_div_data'!$A:$A, 'source merged_div_data'!F:F) < 1073741824, ROUND(XLOOKUP(TEXTJOIN("/", TRUE, $A11:$B11), 'source merged_div_data'!$A:$A, 'source merged_div_data'!F:F)/1048576, 2) & " MB", TRUE, ROUND(XLOOKUP(TEXTJOIN("/", TRUE, $A11:$B11), 'source merged_div_data'!$A:$A, 'source merged_div_data'!F:F)/1073741824, 2) & " GB" ), "×" )} -> 106 B | G11: × | J11: 株式会社Diverse | L11: × | M11: × | N11: 廃止/分社化 | O11: 株式会社Diverse | P11: =IFERROR(__xludf.DUMMYFUNCTION("XLOOKUP(JOIN(""/"",$A11:$B11),'source isilon_divまとめ'!$A:$A,'source isilon_divまとめ'!$D:$D,XLOOKUP(JOIN(""\"",$A11:$B11),'source NetApp-file-sv01-div'!A:A,TEXT('source NetApp-file-sv01-div'!C:C,""yyyy/mm/dd"")))"),"#N/A") -> #N/A
A12: Diverseスタジオ | B12: かいはつ室 | C12: 不明 | D12: =IFERROR(__xludf.DUMMYFUNCTION("XLOOKUP(JOIN(""/"",$A12:$B12),'source merged_div_data'!$A:$A,'source merged_div_data'!B:B)"),2.0) -> 2 | E12: =IFERROR(__xludf.DUMMYFUNCTION("XLOOKUP(JOIN(""/"",$A12:$B12),'source merged_div_data'!$A:$A,'source merged_div_data'!C:C)"),0.0) -> 0 | F12: {=IFERROR( IFS( XLOOKUP(TEXTJOIN("/", TRUE, $A12:$B12), 'source merged_div_data'!$A:$A, 'source merged_div_data'!F:F) < 1024, XLOOKUP(TEXTJOIN("/", TRUE, $A12:$B12), 'source merged_div_data'!$A:$A, 'source merged_div_data'!F:F) & " B", XLOOKUP(TEXTJOIN("/", TRUE, $A12:$B12), 'source merged_div_data'!$A:$A, 'source merged_div_data'!F:F) < 1048576, ROUND(XLOOKUP(TEXTJOIN("/", TRUE, $A12:$B12), 'source merged_div_data'!$A:$A, 'source merged_div_data'!F:F)/1024, 2) & " KB", XLOOKUP(TEXTJOIN("/", TRUE, $A12:$B12), 'source merged_div_data'!$A:$A, 'source merged_div_data'!F:F) < 1073741824, ROUND(XLOOKUP(TEXTJOIN("/", TRUE, $A12:$B12), 'source merged_div_data'!$A:$A, 'source merged_div_data'!F:F)/1048576, 2) & " MB", TRUE, ROUND(XLOOKUP(TEXTJOIN("/", TRUE, $A12:$B12), 'source merged_div_data'!$A:$A, 'source merged_div_data'!F:F)/1073741824, 2) & " GB" ), "×" )} -> 27 B | G12: × | J12: 株式会社Diverse | L12: × | M12: × | N12: 廃止/分社化 | O12: 株式会社Diverse | P12: =IFERROR(__xludf.DUMMYFUNCTION("XLOOKUP(JOIN(""/"",$A12:$B12),'source isilon_divまとめ'!$A:$A,'source isilon_divまとめ'!$D:$D,XLOOKUP(JOIN(""\"",$A12:$B12),'source NetApp-file-sv01-div'!A:A,TEXT('source NetApp-file-sv01-div'!C:C,""yyyy/mm/dd"")))"),"#N/A") -> #N/A
A13: Diverseスタジオ | B13: ビジネス推進室 | C13: 不明 | D13: =IFERROR(__xludf.DUMMYFUNCTION("XLOOKUP(JOIN(""/"",$A13:$B13),'source merged_div_data'!$A:$A,'source merged_div_data'!B:B)"),2.0) -> 2 | E13: =IFERROR(__xludf.DUMMYFUNCTION("XLOOKUP(JOIN(""/"",$A13:$B13),'source merged_div_data'!$A:$A,'source merged_div_data'!C:C)"),0.0) -> 0 | F13: {=IFERROR( IFS( XLOOKUP(TEXTJOIN("/", TRUE, $A13:$B13), 'source merged_div_data'!$A:$A, 'source merged_div_data'!F:F) < 1024, XLOOKUP(TEXTJOIN("/", TRUE, $A13:$B13), 'source merged_div_data'!$A:$A, 'source merged_div_data'!F:F) & " B", XLOOKUP(TEXTJOIN("/", TRUE, $A13:$B13), 'source merged_div_data'!$A:$A, 'source merged_div_data'!F:F) < 1048576, ROUND(XLOOKUP(TEXTJOIN("/", TRUE, $A13:$B13), 'source merged_div_data'!$A:$A, 'source merged_div_data'!F:F)/1024, 2) & " KB", XLOOKUP(TEXTJOIN("/", TRUE, $A13:$B13), 'source merged_div_data'!$A:$A, 'source merged_div_data'!F:F) < 1073741824, ROUND(XLOOKUP(TEXTJOIN("/", TRUE, $A13:$B13), 'source merged_div_data'!$A:$A, 'source merged_div_data'!F:F)/1048576, 2) & " MB", TRUE, ROUND(XLOOKUP(TEXTJOIN("/", TRUE, $A13:$B13), 'source merged_div_data'!$A:$A, 'source merged_div_data'!F:F)/1073741824, 2) & " GB" ), "×" )} -> 27 B | G13: × | J13: 株式会社Diverse | L13: × | M13: × | N13: 廃止/分社化 | O13: 株式会社Diverse | P13: =IFERROR(__xludf.DUMMYFUNCTION("XLOOKUP(JOIN(""/"",$A13:$B13),'source isilon_divまとめ'!$A:$A,'source isilon_divまとめ'!$D:$D,XLOOKUP(JOIN(""\"",$A13:$B13),'source NetApp-file-sv01-div'!A:A,TEXT('source NetApp-file-sv01-div'!C:C,""yyyy/mm/dd"")))"),"#N/A") -> #N/A
A14: Diverseスタジオ | B14: マーケティング室 | C14: 不明 | D14: =IFERROR(__xludf.DUMMYFUNCTION("XLOOKUP(JOIN(""/"",$A14:$B14),'source merged_div_data'!$A:$A,'source merged_div_data'!B:B)"),10.0) -> 10 | E14: =IFERROR(__xludf.DUMMYFUNCTION("XLOOKUP(JOIN(""/"",$A14:$B14),'source merged_div_data'!$A:$A,'source merged_div_data'!C:C)"),0.0) -> 0 | F14: {=IFERROR( IFS( XLOOKUP(TEXTJOIN("/", TRUE, $A14:$B14), 'source merged_div_data'!$A:$A, 'source merged_div_data'!F:F) < 1024, XLOOKUP(TEXTJOIN("/", TRUE, $A14:$B14), 'source merged_div_data'!$A:$A, 'source merged_div_data'!F:F) & " B", XLOOKUP(TEXTJOIN("/", TRUE, $A14:$B14), 'source merged_div_data'!$A:$A, 'source merged_div_data'!F:F) < 1048576, ROUND(XLOOKUP(TEXTJOIN("/", TRUE, $A14:$B14), 'source merged_div_data'!$A:$A, 'source merged_div_data'!F:F)/1024, 2) & " KB", XLOOKUP(TEXTJOIN("/", TRUE, $A14:$B14), 'source merged_div_data'!$A:$A, 'source merged_div_data'!F:F) < 1073741824, ROUND(XLOOKUP(TEXTJOIN("/", TRUE, $A14:$B14), 'source merged_div_data'!$A:$A, 'source merged_div_data'!F:F)/1048576, 2) & " MB", TRUE, ROUND(XLOOKUP(TEXTJOIN("/", TRUE, $A14:$B14), 'source merged_div_data'!$A:$A, 'source merged_div_data'!F:F)/1073741824, 2) & " GB" ), "×" )} -> 288 B | G14: × | J14: 株式会社Diverse | L14: × | M14: × | N14: 廃止/分社化 | O14: 株式会社Diverse | P14: =IFERROR(__xludf.DUMMYFUNCTION("XLOOKUP(JOIN(""/"",$A14:$B14),'source isilon_divまとめ'!$A:$A,'source isilon_divまとめ'!$D:$D,XLOOKUP(JOIN(""\"",$A14:$B14),'source NetApp-file-sv01-div'!A:A,TEXT('source NetApp-file-sv01-div'!C:C,""yyyy/mm/dd"")))"),"#N/A") -> #N/A
A15: Diverseスタジオ | B15: Poiboy事業部 | C15: 不明 | D15: =IFERROR(__xludf.DUMMYFUNCTION("XLOOKUP(JOIN(""/"",$A15:$B15),'source merged_div_data'!$A:$A,'source merged_div_data'!B:B)"),4.0) -> 4 | E15: =IFERROR(__xludf.DUMMYFUNCTION("XLOOKUP(JOIN(""/"",$A15:$B15),'source merged_div_data'!$A:$A,'source merged_div_data'!C:C)"),0.0) -> 0 | F15: {=IFERROR( IFS( XLOOKUP(TEXTJOIN("/", TRUE, $A15:$B15), 'source merged_div_data'!$A:$A, 'source merged_div_data'!F:F) < 1024, XLOOKUP(TEXTJOIN("/", TRUE, $A15:$B15), 'source merged_div_data'!$A:$A, 'source merged_div_data'!F:F) & " B", XLOOKUP(TEXTJOIN("/", TRUE, $A15:$B15), 'source merged_div_data'!$A:$A, 'source merged_div_data'!F:F) < 1048576, ROUND(XLOOKUP(TEXTJOIN("/", TRUE, $A15:$B15), 'source merged_div_data'!$A:$A, 'source merged_div_data'!F:F)/1024, 2) & " KB", XLOOKUP(TEXTJOIN("/", TRUE, $A15:$B15), 'source merged_div_data'!$A:$A, 'source merged_div_data'!F:F) < 1073741824, ROUND(XLOOKUP(TEXTJOIN("/", TRUE, $A15:$B15), 'source merged_div_data'!$A:$A, 'source merged_div_data'!F:F)/1048576, 2) & " MB", TRUE, ROUND(XLOOKUP(TEXTJOIN("/", TRUE, $A15:$B15), 'source merged_div_data'!$A:$A, 'source merged_div_data'!F:F)/1073741824, 2) & " GB" ), "×" )} -> 88 B | G15: × | J15: 株式会社Diverse | L15: × | M15: × | N15: 廃止/分社化 | O15: 株式会社Diverse | P15: =IFERROR(__xludf.DUMMYFUNCTION("XLOOKUP(JOIN(""/"",$A15:$B15),'source isilon_divまとめ'!$A:$A,'source isilon_divまとめ'!$D:$D,XLOOKUP(JOIN(""\"",$A15:$B15),'source NetApp-file-sv01-div'!A:A,TEXT('source NetApp-file-sv01-div'!C:C,""yyyy/mm/dd"")))"),"#N/A") -> #N/A
A16: Diverseスタジオ | B16: 経営管理部 | C16: 仮説 | D16: =IFERROR(__xludf.DUMMYFUNCTION("XLOOKUP(JOIN(""/"",$A16:$B16),'source merged_div_data'!$A:$A,'source merged_div_data'!B:B)"),4342.0) -> 4342 | E16: =IFERROR(__xludf.DUMMYFUNCTION("XLOOKUP(JOIN(""/"",$A16:$B16),'source merged_div_data'!$A:$A,'source merged_div_data'!C:C)"),26544.0) -> 26544 | F16: {=IFERROR( IFS( XLOOKUP(TEXTJOIN("/", TRUE, $A16:$B16), 'source merged_div_data'!$A:$A, 'source merged_div_data'!F:F) < 1024, XLOOKUP(TEXTJOIN("/", TRUE, $A16:$B16), 'source merged_div_data'!$A:$A, 'source merged_div_data'!F:F) & " B", XLOOKUP(TEXTJOIN("/", TRUE, $A16:$B16), 'source merged_div_data'!$A:$A, 'source merged_div_data'!F:F) < 1048576, ROUND(XLOOKUP(TEXTJOIN("/", TRUE, $A16:$B16), 'source merged_div_data'!$A:$A, 'source merged_div_data'!F:F)/1024, 2) & " KB", XLOOKUP(TEXTJOIN("/", TRUE, $A16:$B16), 'source merged_div_data'!$A:$A, 'source merged_div_data'!F:F) < 1073741824, ROUND(XLOOKUP(TEXTJOIN("/", TRUE, $A16:$B16), 'source merged_div_data'!$A:$A, 'source merged_div_data'!F:F)/1048576, 2) & " MB", TRUE, ROUND(XLOOKUP(TEXTJOIN("/", TRUE, $A16:$B16), 'source merged_div_data'!$A:$A, 'source merged_div_data'!F:F)/1073741824, 2) & " GB" ), "×" )} -> 24.1 GB | G16: 2019/03/12 | H16: AWS S3 | J16: 経営管理本部 | K16: 経営管理部 | L16: 野原 孝行 | M16: × | P16: =IFERROR(__xludf.DUMMYFUNCTION("XLOOKUP(JOIN(""/"",$A16:$B16),'source isilon_divまとめ'!$A:$A,'source isilon_divまとめ'!$D:$D,XLOOKUP(JOIN(""\"",$A16:$B16),'source NetApp-file-sv01-div'!A:A,TEXT('source NetApp-file-sv01-div'!C:C,""yyyy/mm/dd"")))"),"2019/03/12") -> 2019/03/12
A17: Diverseスタジオ | B17: 結婚支援事業部 | C17: 不明 | D17: =IFERROR(__xludf.DUMMYFUNCTION("XLOOKUP(JOIN(""/"",$A17:$B17),'source merged_div_data'!$A:$A,'source merged_div_data'!B:B)"),13.0) -> 13 | E17: =IFERROR(__xludf.DUMMYFUNCTION("XLOOKUP(JOIN(""/"",$A17:$B17),'source merged_div_data'!$A:$A,'source merged_div_data'!C:C)"),0.0) -> 0 | F17: {=IFERROR( IFS( XLOOKUP(TEXTJOIN("/", TRUE, $A17:$B17), 'source merged_div_data'!$A:$A, 'source merged_div_data'!F:F) < 1024, XLOOKUP(TEXTJOIN("/", TRUE, $A17:$B17), 'source merged_div_data'!$A:$A, 'source merged_div_data'!F:F) & " B", XLOOKUP(TEXTJOIN("/", TRUE, $A17:$B17), 'source merged_div_data'!$A:$A, 'source merged_div_data'!F:F) < 1048576, ROUND(XLOOKUP(TEXTJOIN("/", TRUE, $A17:$B17), 'source merged_div_data'!$A:$A, 'source merged_div_data'!F:F)/1024, 2) & " KB", XLOOKUP(TEXTJOIN("/", TRUE, $A17:$B17), 'source merged_div_data'!$A:$A, 'source merged_div_data'!F:F) < 1073741824, ROUND(XLOOKUP(TEXTJOIN("/", TRUE, $A17:$B17), 'source merged_div_data'!$A:$A, 'source merged_div_data'!F:F)/1048576, 2) & " MB", TRUE, ROUND(XLOOKUP(TEXTJOIN("/", TRUE, $A17:$B17), 'source merged_div_data'!$A:$A, 'source merged_div_data'!F:F)/1073741824, 2) & " GB" ), "×" )} -> 372 B | G17: × | J17: 株式会社Diverse | L17: × | M17: × | N17: 廃止/分社化 | O17: 株式会社Diverse | P17: =IFERROR(__xludf.DUMMYFUNCTION("XLOOKUP(JOIN(""/"",$A17:$B17),'source isilon_divまとめ'!$A:$A,'source isilon_divまとめ'!$D:$D,XLOOKUP(JOIN(""\"",$A17:$B17),'source NetApp-file-sv01-div'!A:A,TEXT('source NetApp-file-sv01-div'!C:C,""yyyy/mm/dd"")))"),"#N/A") -> #N/A
A18: Diverseスタジオ | B18: 新規サービス事業部 | C18: 不明 | D18: =IFERROR(__xludf.DUMMYFUNCTION("XLOOKUP(JOIN(""/"",$A18:$B18),'source merged_div_data'!$A:$A,'source merged_div_data'!B:B)"),6.0) -> 6 | E18: =IFERROR(__xludf.DUMMYFUNCTION("XLOOKUP(JOIN(""/"",$A18:$B18),'source merged_div_data'!$A:$A,'source merged_div_data'!C:C)"),0.0) -> 0 | F18: {=IFERROR( IFS( XLOOKUP(TEXTJOIN("/", TRUE, $A18:$B18), 'source merged_div_data'!$A:$A, 'source merged_div_data'!F:F) < 1024, XLOOKUP(TEXTJOIN("/", TRUE, $A18:$B18), 'source merged_div_data'!$A:$A, 'source merged_div_data'!F:F) & " B", XLOOKUP(TEXTJOIN("/", TRUE, $A18:$B18), 'source merged_div_data'!$A:$A, 'source merged_div_data'!F:F) < 1048576, ROUND(XLOOKUP(TEXTJOIN("/", TRUE, $A18:$B18), 'source merged_div_data'!$A:$A, 'source merged_div_data'!F:F)/1024, 2) & " KB", XLOOKUP(TEXTJOIN("/", TRUE, $A18:$B18), 'source merged_div_data'!$A:$A, 'source merged_div_data'!F:F) < 1073741824, ROUND(XLOOKUP(TEXTJOIN("/", TRUE, $A18:$B18), 'source merged_div_data'!$A:$A, 'source merged_div_data'!F:F)/1048576, 2) & " MB", TRUE, ROUND(XLOOKUP(TEXTJOIN("/", TRUE, $A18:$B18), 'source merged_div_data'!$A:$A, 'source merged_div_data'!F:F)/1073741824, 2) & " GB" ), "×" )} -> 148 B | G18: × | J18: 株式会社Diverse | L18: × | M18: × | N18: 廃止/分社化 | O18: 株式会社Diverse | P18: =IFERROR(__xludf.DUMMYFUNCTION("XLOOKUP(JOIN(""/"",$A18:$B18),'source isilon_divまとめ'!$A:$A,'source isilon_divまとめ'!$D:$D,XLOOKUP(JOIN(""\"",$A18:$B18),'source NetApp-file-sv01-div'!A:A,TEXT('source NetApp-file-sv01-div'!C:C,""yyyy/mm/dd"")))"),"#N/A") -> #N/A
A19: Diverseスタジオ | B19: youbride事業部 | C19: 不明 | D19: =IFERROR(__xludf.DUMMYFUNCTION("XLOOKUP(JOIN(""/"",$A19:$B19),'source merged_div_data'!$A:$A,'source merged_div_data'!B:B)"),4.0) -> 4 | E19: =IFERROR(__xludf.DUMMYFUNCTION("XLOOKUP(JOIN(""/"",$A19:$B19),'source merged_div_data'!$A:$A,'source merged_div_data'!C:C)"),0.0) -> 0 | F19: {=IFERROR( IFS( XLOOKUP(TEXTJOIN("/", TRUE, $A19:$B19), 'source merged_div_data'!$A:$A, 'source merged_div_data'!F:F) < 1024, XLOOKUP(TEXTJOIN("/", TRUE, $A19:$B19), 'source merged_div_data'!$A:$A, 'source merged_div_data'!F:F) & " B", XLOOKUP(TEXTJOIN("/", TRUE, $A19:$B19), 'source merged_div_data'!$A:$A, 'source merged_div_data'!F:F) < 1048576, ROUND(XLOOKUP(TEXTJOIN("/", TRUE, $A19:$B19), 'source merged_div_data'!$A:$A, 'source merged_div_data'!F:F)/1024, 2) & " KB", XLOOKUP(TEXTJOIN("/", TRUE, $A19:$B19), 'source merged_div_data'!$A:$A, 'source merged_div_data'!F:F) < 1073741824, ROUND(XLOOKUP(TEXTJOIN("/", TRUE, $A19:$B19), 'source merged_div_data'!$A:$A, 'source merged_div_data'!F:F)/1048576, 2) & " MB", TRUE, ROUND(XLOOKUP(TEXTJOIN("/", TRUE, $A19:$B19), 'source merged_div_data'!$A:$A, 'source merged_div_data'!F:F)/1073741824, 2) & " GB" ), "×" )} -> 90 B | G19: × | J19: 株式会社Diverse | L19: × | M19: × | N19: 廃止/分社化 | O19: 株式会社Diverse | P19: =IFERROR(__xludf.DUMMYFUNCTION("XLOOKUP(JOIN(""/"",$A19:$B19),'source isilon_divまとめ'!$A:$A,'source isilon_divまとめ'!$D:$D,XLOOKUP(JOIN(""\"",$A19:$B19),'source NetApp-file-sv01-div'!A:A,TEXT('source NetApp-file-sv01-div'!C:C,""yyyy/mm/dd"")))"),"#N/A") -> #N/A
A20: Diverseスタジオ | B20: 健全化推進室 | C20: 不明 | D20: =IFERROR(__xludf.DUMMYFUNCTION("XLOOKUP(JOIN(""/"",$A20:$B20),'source merged_div_data'!$A:$A,'source merged_div_data'!B:B)"),2.0) -> 2 | E20: =IFERROR(__xludf.DUMMYFUNCTION("XLOOKUP(JOIN(""/"",$A20:$B20),'source merged_div_data'!$A:$A,'source merged_div_data'!C:C)"),0.0) -> 0 | F20: {=IFERROR( IFS( XLOOKUP(TEXTJOIN("/", TRUE, $A20:$B20), 'source merged_div_data'!$A:$A, 'source merged_div_data'!F:F) < 1024, XLOOKUP(TEXTJOIN("/", TRUE, $A20:$B20), 'source merged_div_data'!$A:$A, 'source merged_div_data'!F:F) & " B", XLOOKUP(TEXTJOIN("/", TRUE, $A20:$B20), 'source merged_div_data'!$A:$A, 'source merged_div_data'!F:F) < 1048576, ROUND(XLOOKUP(TEXTJOIN("/", TRUE, $A20:$B20), 'source merged_div_data'!$A:$A, 'source merged_div_data'!F:F)/1024, 2) & " KB", XLOOKUP(TEXTJOIN("/", TRUE, $A20:$B20), 'source merged_div_data'!$A:$A, 'source merged_div_data'!F:F) < 1073741824, ROUND(XLOOKUP(TEXTJOIN("/", TRUE, $A20:$B20), 'source merged_div_data'!$A:$A, 'source merged_div_data'!F:F)/1048576, 2) & " MB", TRUE, ROUND(XLOOKUP(TEXTJOIN("/", TRUE, $A20:$B20), 'source merged_div_data'!$A:$A, 'source merged_div_data'!F:F)/1073741824, 2) & " GB" ), "×" )} -> 27 B | G20: × | J20: 株式会社Diverse | L20: × | M20: × | N20: 廃止/分社化 | O20: 株式会社Diverse | P20: =IFERROR(__xludf.DUMMYFUNCTION("XLOOKUP(JOIN(""/"",$A20:$B20),'source isilon_divまとめ'!$A:$A,'source isilon_divまとめ'!$D:$D,XLOOKUP(JOIN(""\"",$A20:$B20),'source NetApp-file-sv01-div'!A:A,TEXT('source NetApp-file-sv01-div'!C:C,""yyyy/mm/dd"")))"),"#N/A") -> #N/A
A21: Diverseスタジオ | B21: 技術研究所 | C21: 不明 | D21: =IFERROR(__xludf.DUMMYFUNCTION("XLOOKUP(JOIN(""/"",$A21:$B21),'source merged_div_data'!$A:$A,'source merged_div_data'!B:B)"),2.0) -> 2 | E21: =IFERROR(__xludf.DUMMYFUNCTION("XLOOKUP(JOIN(""/"",$A21:$B21),'source merged_div_data'!$A:$A,'source merged_div_data'!C:C)"),0.0) -> 0 | F21: {=IFERROR( IFS( XLOOKUP(TEXTJOIN("/", TRUE, $A21:$B21), 'source merged_div_data'!$A:$A, 'source merged_div_data'!F:F) < 1024, XLOOKUP(TEXTJOIN("/", TRUE, $A21:$B21), 'source merged_div_data'!$A:$A, 'source merged_div_data'!F:F) & " B", XLOOKUP(TEXTJOIN("/", TRUE, $A21:$B21), 'source merged_div_data'!$A:$A, 'source merged_div_data'!F:F) < 1048576, ROUND(XLOOKUP(TEXTJOIN("/", TRUE, $A21:$B21), 'source merged_div_data'!$A:$A, 'source merged_div_data'!F:F)/1024, 2) & " KB", XLOOKUP(TEXTJOIN("/", TRUE, $A21:$B21), 'source merged_div_data'!$A:$A, 'source merged_div_data'!F:F) < 1073741824, ROUND(XLOOKUP(TEXTJOIN("/", TRUE, $A21:$B21), 'source merged_div_data'!$A:$A, 'source merged_div_data'!F:F)/1048576, 2) & " MB", TRUE, ROUND(XLOOKUP(TEXTJOIN("/", TRUE, $A21:$B21), 'source merged_div_data'!$A:$A, 'source merged_div_data'!F:F)/1073741824, 2) & " GB" ), "×" )} -> 27 B | G21: × | J21: 株式会社Diverse | L21: × | M21: × | N21: 廃止/分社化 | O21: 株式会社Diverse | P21: =IFERROR(__xludf.DUMMYFUNCTION("XLOOKUP(JOIN(""/"",$A21:$B21),'source isilon_divまとめ'!$A:$A,'source isilon_divまとめ'!$D:$D,XLOOKUP(JOIN(""\"",$A21:$B21),'source NetApp-file-sv01-div'!A:A,TEXT('source NetApp-file-sv01-div'!C:C,""yyyy/mm/dd"")))"),"#N/A") -> #N/A
A22: Diverseスタジオ | B22: VEAT事業部 | C22: 不明 | D22: =IFERROR(__xludf.DUMMYFUNCTION("XLOOKUP(JOIN(""/"",$A22:$B22),'source merged_div_data'!$A:$A,'source merged_div_data'!B:B)"),4.0) -> 4 | E22: =IFERROR(__xludf.DUMMYFUNCTION("XLOOKUP(JOIN(""/"",$A22:$B22),'source merged_div_data'!$A:$A,'source merged_div_data'!C:C)"),0.0) -> 0 | F22: {=IFERROR( IFS( XLOOKUP(TEXTJOIN("/", TRUE, $A22:$B22), 'source merged_div_data'!$A:$A, 'source merged_div_data'!F:F) < 1024, XLOOKUP(TEXTJOIN("/", TRUE, $A22:$B22), 'source merged_div_data'!$A:$A, 'source merged_div_data'!F:F) & " B", XLOOKUP(TEXTJOIN("/", TRUE, $A22:$B22), 'source merged_div_data'!$A:$A, 'source merged_div_data'!F:F) < 1048576, ROUND(XLOOKUP(TEXTJOIN("/", TRUE, $A22:$B22), 'source merged_div_data'!$A:$A, 'source merged_div_data'!F:F)/1024, 2) & " KB", XLOOKUP(TEXTJOIN("/", TRUE, $A22:$B22), 'source merged_div_data'!$A:$A, 'source merged_div_data'!F:F) < 1073741824, ROUND(XLOOKUP(TEXTJOIN("/", TRUE, $A22:$B22), 'source merged_div_data'!$A:$A, 'source merged_div_data'!F:F)/1048576, 2) & " MB", TRUE, ROUND(XLOOKUP(TEXTJOIN("/", TRUE, $A22:$B22), 'source merged_div_data'!$A:$A, 'source merged_div_data'!F:F)/1073741824, 2) & " GB" ), "×" )} -> 86 B | G22: {=IFERROR( IFS( XLOOKUP(TEXTJOIN("/", TRUE, $A22:$B22), 'source merged_div_data'!$A:$A, 'source merged_div_data'!G:G) < 1024, XLOOKUP(TEXTJOIN("/", TRUE, $A22:$B22), 'source merged_div_data'!$A:$A, 'source merged_div_data'!G:G) & " B", XLOOKUP(TEXTJOIN("/", TRUE, $A22:$B22), 'source merged_div_data'!$A:$A, 'source merged_div_data'!G:G) < 1048576, ROUND(XLOOKUP(TEXTJOIN("/", TRUE, $A22:$B22), 'source merged_div_data'!$A:$A, 'source merged_div_data'!G:G)/1024, 2) & " KB", XLOOKUP(TEXTJOIN("/", TRUE, $A22:$B22), 'source merged_div_data'!$A:$A, 'source merged_div_data'!G:G) < 1073741824, ROUND(XLOOKUP(TEXTJOIN("/", TRUE, $A22:$B22), 'source merged_div_data'!$A:$A, 'source merged_div_data'!G:G)/1048576, 2) & " MB", TRUE, ROUND(XLOOKUP(TEXTJOIN("/", TRUE, $A22:$B22), 'source merged_div_data'!$A:$A, 'source merged_div_data'!G:G)/1073741824, 2) & " GB" ), "×" )} -> 128 KB | J22: 株式会社Diverse | L22: × | M22: × | N22: 廃止/分社化 | O22: 株式会社Diverse | P22: =IFERROR(__xludf.DUMMYFUNCTION("XLOOKUP(JOIN(""/"",$A22:$B22),'source isilon_divまとめ'!$A:$A,'source isilon_divまとめ'!$D:$D,XLOOKUP(JOIN(""\"",$A22:$B22),'source NetApp-file-sv01-div'!A:A,TEXT('source NetApp-file-sv01-div'!C:C,""yyyy/mm/dd"")))"),"#N/A") -> #N/A
